Traceback (most recent call last):
  File "/home/xgrdscpi/api.eccomerce.digitaltek.co.in/passenger_wsgi.py", line 4, in <module>
    from backend.wsgi import application
  File "/home/xgrdscpi/api.eccomerce.digitaltek.co.in/backend/wsgi.py", line 16, in <module>
    application = get_wsgi_application()
  File "/home/xgrdscpi/virtualenv/api.eccomerce.digitaltek.co.in/3.8/lib/python3.8/site-packages/django/core/wsgi.py", line 12, in get_wsgi_application
    django.setup(set_prefix=False)
  File "/home/xgrdscpi/virtualenv/api.eccomerce.digitaltek.co.in/3.8/lib/python3.8/site-packages/django/__init__.py", line 19, in setup
    configure_logging(settings.LOGGING_CONFIG, settings.LOGGING)
  File "/home/xgrdscpi/virtualenv/api.eccomerce.digitaltek.co.in/3.8/lib/python3.8/site-packages/django/conf/__init__.py", line 102, in __getattr__
    self._setup(name)
  File "/home/xgrdscpi/virtualenv/api.eccomerce.digitaltek.co.in/3.8/lib/python3.8/site-packages/django/conf/__init__.py", line 89, in _setup
    self._wrapped = Settings(settings_module)
  File "/home/xgrdscpi/virtualenv/api.eccomerce.digitaltek.co.in/3.8/lib/python3.8/site-packages/django/conf/__init__.py", line 217, in __init__
    mod = importlib.import_module(self.SETTINGS_MODULE)
  File "/opt/alt/python38/lib64/python3.8/importlib/__init__.py", line 127, in import_module
    return _bootstrap._gcd_import(name[level:], package, level)
  File "/home/xgrdscpi/api.eccomerce.digitaltek.co.in/backend/settings.py", line 26, in <module>
    SECRET_KEY = config('SECRET_KEY')
  File "/home/xgrdscpi/virtualenv/api.eccomerce.digitaltek.co.in/3.8/lib/python3.8/site-packages/decouple.py", line 248, in __call__
    return self.config(*args, **kwargs)
  File "/home/xgrdscpi/virtualenv/api.eccomerce.digitaltek.co.in/3.8/lib/python3.8/site-packages/decouple.py", line 107, in __call__
    return self.get(*args, **kwargs)
  File "/home/xgrdscpi/virtualenv/api.eccomerce.digitaltek.co.in/3.8/lib/python3.8/site-packages/decouple.py", line 92, in get
    raise UndefinedValueError('{} not found. Declare it as envvar or define a default value.'.format(option))
decouple.UndefinedValueError: SECRET_KEY not found. Declare it as envvar or define a default value.
Traceback (most recent call last):
  File "/home/xgrdscpi/api.eccomerce.digitaltek.co.in/passenger_wsgi.py", line 4, in <module>
    from backend.wsgi import application
  File "/home/xgrdscpi/api.eccomerce.digitaltek.co.in/backend/wsgi.py", line 16, in <module>
    application = get_wsgi_application()
  File "/home/xgrdscpi/virtualenv/api.eccomerce.digitaltek.co.in/3.8/lib/python3.8/site-packages/django/core/wsgi.py", line 12, in get_wsgi_application
    django.setup(set_prefix=False)
  File "/home/xgrdscpi/virtualenv/api.eccomerce.digitaltek.co.in/3.8/lib/python3.8/site-packages/django/__init__.py", line 19, in setup
    configure_logging(settings.LOGGING_CONFIG, settings.LOGGING)
  File "/home/xgrdscpi/virtualenv/api.eccomerce.digitaltek.co.in/3.8/lib/python3.8/site-packages/django/conf/__init__.py", line 102, in __getattr__
    self._setup(name)
  File "/home/xgrdscpi/virtualenv/api.eccomerce.digitaltek.co.in/3.8/lib/python3.8/site-packages/django/conf/__init__.py", line 89, in _setup
    self._wrapped = Settings(settings_module)
  File "/home/xgrdscpi/virtualenv/api.eccomerce.digitaltek.co.in/3.8/lib/python3.8/site-packages/django/conf/__init__.py", line 217, in __init__
    mod = importlib.import_module(self.SETTINGS_MODULE)
  File "/opt/alt/python38/lib64/python3.8/importlib/__init__.py", line 127, in import_module
    return _bootstrap._gcd_import(name[level:], package, level)
  File "/home/xgrdscpi/api.eccomerce.digitaltek.co.in/backend/settings.py", line 26, in <module>
    SECRET_KEY = config('SECRET_KEY')
  File "/home/xgrdscpi/virtualenv/api.eccomerce.digitaltek.co.in/3.8/lib/python3.8/site-packages/decouple.py", line 248, in __call__
    return self.config(*args, **kwargs)
  File "/home/xgrdscpi/virtualenv/api.eccomerce.digitaltek.co.in/3.8/lib/python3.8/site-packages/decouple.py", line 107, in __call__
    return self.get(*args, **kwargs)
  File "/home/xgrdscpi/virtualenv/api.eccomerce.digitaltek.co.in/3.8/lib/python3.8/site-packages/decouple.py", line 92, in get
    raise UndefinedValueError('{} not found. Declare it as envvar or define a default value.'.format(option))
decouple.UndefinedValueError: SECRET_KEY not found. Declare it as envvar or define a default value.
[UID:4986][2403833] Child process with pid: 2403876 was killed by signal: 15, core dump: 0
Traceback (most recent call last):
  File "/home/xgrdscpi/api.eccomerce.digitaltek.co.in/passenger_wsgi.py", line 4, in <module>
    from backend.wsgi import application
  File "/home/xgrdscpi/api.eccomerce.digitaltek.co.in/backend/wsgi.py", line 16, in <module>
    application = get_wsgi_application()
  File "/home/xgrdscpi/virtualenv/api.eccomerce.digitaltek.co.in/3.8/lib/python3.8/site-packages/django/core/wsgi.py", line 12, in get_wsgi_application
    django.setup(set_prefix=False)
  File "/home/xgrdscpi/virtualenv/api.eccomerce.digitaltek.co.in/3.8/lib/python3.8/site-packages/django/__init__.py", line 19, in setup
    configure_logging(settings.LOGGING_CONFIG, settings.LOGGING)
  File "/home/xgrdscpi/virtualenv/api.eccomerce.digitaltek.co.in/3.8/lib/python3.8/site-packages/django/conf/__init__.py", line 102, in __getattr__
    self._setup(name)
  File "/home/xgrdscpi/virtualenv/api.eccomerce.digitaltek.co.in/3.8/lib/python3.8/site-packages/django/conf/__init__.py", line 89, in _setup
    self._wrapped = Settings(settings_module)
  File "/home/xgrdscpi/virtualenv/api.eccomerce.digitaltek.co.in/3.8/lib/python3.8/site-packages/django/conf/__init__.py", line 217, in __init__
    mod = importlib.import_module(self.SETTINGS_MODULE)
  File "/opt/alt/python38/lib64/python3.8/importlib/__init__.py", line 127, in import_module
    return _bootstrap._gcd_import(name[level:], package, level)
  File "/home/xgrdscpi/api.eccomerce.digitaltek.co.in/backend/settings.py", line 26, in <module>
    SECRET_KEY = config('SECRET_KEY')
  File "/home/xgrdscpi/virtualenv/api.eccomerce.digitaltek.co.in/3.8/lib/python3.8/site-packages/decouple.py", line 248, in __call__
    return self.config(*args, **kwargs)
  File "/home/xgrdscpi/virtualenv/api.eccomerce.digitaltek.co.in/3.8/lib/python3.8/site-packages/decouple.py", line 107, in __call__
    return self.get(*args, **kwargs)
  File "/home/xgrdscpi/virtualenv/api.eccomerce.digitaltek.co.in/3.8/lib/python3.8/site-packages/decouple.py", line 92, in get
    raise UndefinedValueError('{} not found. Declare it as envvar or define a default value.'.format(option))
decouple.UndefinedValueError: SECRET_KEY not found. Declare it as envvar or define a default value.
[UID:4986][2403833] Child process with pid: 2414037 was killed by signal: 15, core dump: 0
Traceback (most recent call last):
  File "/home/xgrdscpi/api.eccomerce.digitaltek.co.in/passenger_wsgi.py", line 4, in <module>
    from backend.wsgi import application
  File "/home/xgrdscpi/api.eccomerce.digitaltek.co.in/backend/wsgi.py", line 16, in <module>
    application = get_wsgi_application()
  File "/home/xgrdscpi/virtualenv/api.eccomerce.digitaltek.co.in/3.8/lib/python3.8/site-packages/django/core/wsgi.py", line 12, in get_wsgi_application
    django.setup(set_prefix=False)
  File "/home/xgrdscpi/virtualenv/api.eccomerce.digitaltek.co.in/3.8/lib/python3.8/site-packages/django/__init__.py", line 19, in setup
    configure_logging(settings.LOGGING_CONFIG, settings.LOGGING)
  File "/home/xgrdscpi/virtualenv/api.eccomerce.digitaltek.co.in/3.8/lib/python3.8/site-packages/django/conf/__init__.py", line 102, in __getattr__
    self._setup(name)
  File "/home/xgrdscpi/virtualenv/api.eccomerce.digitaltek.co.in/3.8/lib/python3.8/site-packages/django/conf/__init__.py", line 89, in _setup
    self._wrapped = Settings(settings_module)
  File "/home/xgrdscpi/virtualenv/api.eccomerce.digitaltek.co.in/3.8/lib/python3.8/site-packages/django/conf/__init__.py", line 217, in __init__
    mod = importlib.import_module(self.SETTINGS_MODULE)
  File "/opt/alt/python38/lib64/python3.8/importlib/__init__.py", line 127, in import_module
    return _bootstrap._gcd_import(name[level:], package, level)
  File "/home/xgrdscpi/api.eccomerce.digitaltek.co.in/backend/settings.py", line 26, in <module>
    SECRET_KEY = config('SECRET_KEY')
  File "/home/xgrdscpi/virtualenv/api.eccomerce.digitaltek.co.in/3.8/lib/python3.8/site-packages/decouple.py", line 248, in __call__
    return self.config(*args, **kwargs)
  File "/home/xgrdscpi/virtualenv/api.eccomerce.digitaltek.co.in/3.8/lib/python3.8/site-packages/decouple.py", line 107, in __call__
    return self.get(*args, **kwargs)
  File "/home/xgrdscpi/virtualenv/api.eccomerce.digitaltek.co.in/3.8/lib/python3.8/site-packages/decouple.py", line 92, in get
    raise UndefinedValueError('{} not found. Declare it as envvar or define a default value.'.format(option))
decouple.UndefinedValueError: SECRET_KEY not found. Declare it as envvar or define a default value.
[UID:4986][2403833] Child process with pid: 2414622 was killed by signal: 15, core dump: 0
Traceback (most recent call last):
  File "/home/xgrdscpi/api.eccomerce.digitaltek.co.in/passenger_wsgi.py", line 4, in <module>
    from backend.wsgi import application
  File "/home/xgrdscpi/api.eccomerce.digitaltek.co.in/backend/wsgi.py", line 16, in <module>
    application = get_wsgi_application()
  File "/home/xgrdscpi/virtualenv/api.eccomerce.digitaltek.co.in/3.8/lib/python3.8/site-packages/django/core/wsgi.py", line 12, in get_wsgi_application
    django.setup(set_prefix=False)
  File "/home/xgrdscpi/virtualenv/api.eccomerce.digitaltek.co.in/3.8/lib/python3.8/site-packages/django/__init__.py", line 19, in setup
    configure_logging(settings.LOGGING_CONFIG, settings.LOGGING)
  File "/home/xgrdscpi/virtualenv/api.eccomerce.digitaltek.co.in/3.8/lib/python3.8/site-packages/django/conf/__init__.py", line 102, in __getattr__
    self._setup(name)
  File "/home/xgrdscpi/virtualenv/api.eccomerce.digitaltek.co.in/3.8/lib/python3.8/site-packages/django/conf/__init__.py", line 89, in _setup
    self._wrapped = Settings(settings_module)
  File "/home/xgrdscpi/virtualenv/api.eccomerce.digitaltek.co.in/3.8/lib/python3.8/site-packages/django/conf/__init__.py", line 217, in __init__
    mod = importlib.import_module(self.SETTINGS_MODULE)
  File "/opt/alt/python38/lib64/python3.8/importlib/__init__.py", line 127, in import_module
    return _bootstrap._gcd_import(name[level:], package, level)
  File "/home/xgrdscpi/api.eccomerce.digitaltek.co.in/backend/settings.py", line 26, in <module>
    SECRET_KEY = config('SECRET_KEY')
  File "/home/xgrdscpi/virtualenv/api.eccomerce.digitaltek.co.in/3.8/lib/python3.8/site-packages/decouple.py", line 248, in __call__
    return self.config(*args, **kwargs)
  File "/home/xgrdscpi/virtualenv/api.eccomerce.digitaltek.co.in/3.8/lib/python3.8/site-packages/decouple.py", line 107, in __call__
    return self.get(*args, **kwargs)
  File "/home/xgrdscpi/virtualenv/api.eccomerce.digitaltek.co.in/3.8/lib/python3.8/site-packages/decouple.py", line 92, in get
    raise UndefinedValueError('{} not found. Declare it as envvar or define a default value.'.format(option))
decouple.UndefinedValueError: SECRET_KEY not found. Declare it as envvar or define a default value.
Traceback (most recent call last):
  File "/home/xgrdscpi/api.eccomerce.digitaltek.co.in/passenger_wsgi.py", line 4, in <module>
    from backend.wsgi import application
  File "/home/xgrdscpi/api.eccomerce.digitaltek.co.in/backend/wsgi.py", line 16, in <module>
    application = get_wsgi_application()
  File "/home/xgrdscpi/virtualenv/api.eccomerce.digitaltek.co.in/3.8/lib/python3.8/site-packages/django/core/wsgi.py", line 12, in get_wsgi_application
    django.setup(set_prefix=False)
  File "/home/xgrdscpi/virtualenv/api.eccomerce.digitaltek.co.in/3.8/lib/python3.8/site-packages/django/__init__.py", line 19, in setup
    configure_logging(settings.LOGGING_CONFIG, settings.LOGGING)
  File "/home/xgrdscpi/virtualenv/api.eccomerce.digitaltek.co.in/3.8/lib/python3.8/site-packages/django/conf/__init__.py", line 102, in __getattr__
    self._setup(name)
  File "/home/xgrdscpi/virtualenv/api.eccomerce.digitaltek.co.in/3.8/lib/python3.8/site-packages/django/conf/__init__.py", line 89, in _setup
    self._wrapped = Settings(settings_module)
  File "/home/xgrdscpi/virtualenv/api.eccomerce.digitaltek.co.in/3.8/lib/python3.8/site-packages/django/conf/__init__.py", line 217, in __init__
    mod = importlib.import_module(self.SETTINGS_MODULE)
  File "/opt/alt/python38/lib64/python3.8/importlib/__init__.py", line 127, in import_module
    return _bootstrap._gcd_import(name[level:], package, level)
  File "/home/xgrdscpi/api.eccomerce.digitaltek.co.in/backend/settings.py", line 26, in <module>
    SECRET_KEY = config('SECRET_KEY')
  File "/home/xgrdscpi/virtualenv/api.eccomerce.digitaltek.co.in/3.8/lib/python3.8/site-packages/decouple.py", line 248, in __call__
    return self.config(*args, **kwargs)
  File "/home/xgrdscpi/virtualenv/api.eccomerce.digitaltek.co.in/3.8/lib/python3.8/site-packages/decouple.py", line 107, in __call__
    return self.get(*args, **kwargs)
  File "/home/xgrdscpi/virtualenv/api.eccomerce.digitaltek.co.in/3.8/lib/python3.8/site-packages/decouple.py", line 92, in get
    raise UndefinedValueError('{} not found. Declare it as envvar or define a default value.'.format(option))
decouple.UndefinedValueError: SECRET_KEY not found. Declare it as envvar or define a default value.
[UID:4986][2492848] Child process with pid: 2493073 was killed by signal: 15, core dump: 0
Traceback (most recent call last):
  File "/home/xgrdscpi/api.eccomerce.digitaltek.co.in/passenger_wsgi.py", line 4, in <module>
    from backend.wsgi import application
  File "/home/xgrdscpi/api.eccomerce.digitaltek.co.in/backend/wsgi.py", line 16, in <module>
    application = get_wsgi_application()
  File "/home/xgrdscpi/virtualenv/api.eccomerce.digitaltek.co.in/3.8/lib/python3.8/site-packages/django/core/wsgi.py", line 12, in get_wsgi_application
    django.setup(set_prefix=False)
  File "/home/xgrdscpi/virtualenv/api.eccomerce.digitaltek.co.in/3.8/lib/python3.8/site-packages/django/__init__.py", line 19, in setup
    configure_logging(settings.LOGGING_CONFIG, settings.LOGGING)
  File "/home/xgrdscpi/virtualenv/api.eccomerce.digitaltek.co.in/3.8/lib/python3.8/site-packages/django/conf/__init__.py", line 102, in __getattr__
    self._setup(name)
  File "/home/xgrdscpi/virtualenv/api.eccomerce.digitaltek.co.in/3.8/lib/python3.8/site-packages/django/conf/__init__.py", line 89, in _setup
    self._wrapped = Settings(settings_module)
  File "/home/xgrdscpi/virtualenv/api.eccomerce.digitaltek.co.in/3.8/lib/python3.8/site-packages/django/conf/__init__.py", line 217, in __init__
    mod = importlib.import_module(self.SETTINGS_MODULE)
  File "/opt/alt/python38/lib64/python3.8/importlib/__init__.py", line 127, in import_module
    return _bootstrap._gcd_import(name[level:], package, level)
  File "/home/xgrdscpi/api.eccomerce.digitaltek.co.in/backend/settings.py", line 26, in <module>
    SECRET_KEY = config('SECRET_KEY')
  File "/home/xgrdscpi/virtualenv/api.eccomerce.digitaltek.co.in/3.8/lib/python3.8/site-packages/decouple.py", line 248, in __call__
    return self.config(*args, **kwargs)
  File "/home/xgrdscpi/virtualenv/api.eccomerce.digitaltek.co.in/3.8/lib/python3.8/site-packages/decouple.py", line 107, in __call__
    return self.get(*args, **kwargs)
  File "/home/xgrdscpi/virtualenv/api.eccomerce.digitaltek.co.in/3.8/lib/python3.8/site-packages/decouple.py", line 92, in get
    raise UndefinedValueError('{} not found. Declare it as envvar or define a default value.'.format(option))
decouple.UndefinedValueError: SECRET_KEY not found. Declare it as envvar or define a default value.
[UID:4986][2492848] Child process with pid: 2494106 was killed by signal: 15, core dump: 0
Not Found: /
Not Found: /favicon.ico
[UID:4986][1051802] Child process with pid: 1053025 was killed by signal: 15, core dump: 0
[UID:4986][2268119] Child process with pid: 2269024 was killed by signal: 15, core dump: 0
[UID:4986][2503582] Child process with pid: 2503648 was killed by signal: 15, core dump: 0
[UID:4986][847155] Child process with pid: 896184 was killed by signal: 15, core dump: 0
Error blacklisting refresh token: Token is invalid or expired
Error blacklisting refresh token: Token is invalid or expired
Error blacklisting refresh token: Token is blacklisted
Error blacklisting refresh token: Token is blacklisted
Traceback (most recent call last):
  File "/home/xgrdscpi/api.lulucollection-52.digitaltek.co.in/passenger_wsgi.py", line 4, in <module>
    from backend.wsgi import application
  File "/home/xgrdscpi/api.lulucollection-52.digitaltek.co.in/backend/wsgi.py", line 16, in <module>
    application = get_wsgi_application()
  File "/home/xgrdscpi/virtualenv/api.lulucollection-52.digitaltek.co.in/3.8/lib/python3.8/site-packages/django/core/wsgi.py", line 12, in get_wsgi_application
    django.setup(set_prefix=False)
  File "/home/xgrdscpi/virtualenv/api.lulucollection-52.digitaltek.co.in/3.8/lib/python3.8/site-packages/django/__init__.py", line 19, in setup
    configure_logging(settings.LOGGING_CONFIG, settings.LOGGING)
  File "/home/xgrdscpi/virtualenv/api.lulucollection-52.digitaltek.co.in/3.8/lib/python3.8/site-packages/django/conf/__init__.py", line 102, in __getattr__
    self._setup(name)
  File "/home/xgrdscpi/virtualenv/api.lulucollection-52.digitaltek.co.in/3.8/lib/python3.8/site-packages/django/conf/__init__.py", line 89, in _setup
    self._wrapped = Settings(settings_module)
  File "/home/xgrdscpi/virtualenv/api.lulucollection-52.digitaltek.co.in/3.8/lib/python3.8/site-packages/django/conf/__init__.py", line 217, in __init__
    mod = importlib.import_module(self.SETTINGS_MODULE)
  File "/opt/alt/python38/lib64/python3.8/importlib/__init__.py", line 127, in import_module
    return _bootstrap._gcd_import(name[level:], package, level)
  File "/home/xgrdscpi/api.lulucollection-52.digitaltek.co.in/backend/settings.py", line 26, in <module>
    SECRET_KEY = config('SECRET_KEY')
  File "/home/xgrdscpi/virtualenv/api.lulucollection-52.digitaltek.co.in/3.8/lib/python3.8/site-packages/decouple.py", line 248, in __call__
    return self.config(*args, **kwargs)
  File "/home/xgrdscpi/virtualenv/api.lulucollection-52.digitaltek.co.in/3.8/lib/python3.8/site-packages/decouple.py", line 107, in __call__
    return self.get(*args, **kwargs)
  File "/home/xgrdscpi/virtualenv/api.lulucollection-52.digitaltek.co.in/3.8/lib/python3.8/site-packages/decouple.py", line 92, in get
    raise UndefinedValueError('{} not found. Declare it as envvar or define a default value.'.format(option))
decouple.UndefinedValueError: SECRET_KEY not found. Declare it as envvar or define a default value.
Traceback (most recent call last):
  File "/home/xgrdscpi/api.lulucollection-52.digitaltek.co.in/passenger_wsgi.py", line 4, in <module>
    from backend.wsgi import application
  File "/home/xgrdscpi/api.lulucollection-52.digitaltek.co.in/backend/wsgi.py", line 16, in <module>
    application = get_wsgi_application()
  File "/home/xgrdscpi/virtualenv/api.lulucollection-52.digitaltek.co.in/3.8/lib/python3.8/site-packages/django/core/wsgi.py", line 12, in get_wsgi_application
    django.setup(set_prefix=False)
  File "/home/xgrdscpi/virtualenv/api.lulucollection-52.digitaltek.co.in/3.8/lib/python3.8/site-packages/django/__init__.py", line 19, in setup
    configure_logging(settings.LOGGING_CONFIG, settings.LOGGING)
  File "/home/xgrdscpi/virtualenv/api.lulucollection-52.digitaltek.co.in/3.8/lib/python3.8/site-packages/django/conf/__init__.py", line 102, in __getattr__
    self._setup(name)
  File "/home/xgrdscpi/virtualenv/api.lulucollection-52.digitaltek.co.in/3.8/lib/python3.8/site-packages/django/conf/__init__.py", line 89, in _setup
    self._wrapped = Settings(settings_module)
  File "/home/xgrdscpi/virtualenv/api.lulucollection-52.digitaltek.co.in/3.8/lib/python3.8/site-packages/django/conf/__init__.py", line 217, in __init__
    mod = importlib.import_module(self.SETTINGS_MODULE)
  File "/opt/alt/python38/lib64/python3.8/importlib/__init__.py", line 127, in import_module
    return _bootstrap._gcd_import(name[level:], package, level)
  File "/home/xgrdscpi/api.lulucollection-52.digitaltek.co.in/backend/settings.py", line 26, in <module>
    SECRET_KEY = config('SECRET_KEY')
  File "/home/xgrdscpi/virtualenv/api.lulucollection-52.digitaltek.co.in/3.8/lib/python3.8/site-packages/decouple.py", line 248, in __call__
    return self.config(*args, **kwargs)
  File "/home/xgrdscpi/virtualenv/api.lulucollection-52.digitaltek.co.in/3.8/lib/python3.8/site-packages/decouple.py", line 107, in __call__
    return self.get(*args, **kwargs)
  File "/home/xgrdscpi/virtualenv/api.lulucollection-52.digitaltek.co.in/3.8/lib/python3.8/site-packages/decouple.py", line 92, in get
    raise UndefinedValueError('{} not found. Declare it as envvar or define a default value.'.format(option))
decouple.UndefinedValueError: SECRET_KEY not found. Declare it as envvar or define a default value.
[UID:4986][2831005] Child process with pid: 2831069 was killed by signal: 15, core dump: 0
Traceback (most recent call last):
  File "/home/xgrdscpi/api.lulucollection-52.digitaltek.co.in/passenger_wsgi.py", line 4, in <module>
    from backend.wsgi import application
  File "/home/xgrdscpi/api.lulucollection-52.digitaltek.co.in/backend/wsgi.py", line 16, in <module>
    application = get_wsgi_application()
  File "/home/xgrdscpi/virtualenv/api.lulucollection-52.digitaltek.co.in/3.8/lib/python3.8/site-packages/django/core/wsgi.py", line 12, in get_wsgi_application
    django.setup(set_prefix=False)
  File "/home/xgrdscpi/virtualenv/api.lulucollection-52.digitaltek.co.in/3.8/lib/python3.8/site-packages/django/__init__.py", line 19, in setup
    configure_logging(settings.LOGGING_CONFIG, settings.LOGGING)
  File "/home/xgrdscpi/virtualenv/api.lulucollection-52.digitaltek.co.in/3.8/lib/python3.8/site-packages/django/conf/__init__.py", line 102, in __getattr__
    self._setup(name)
  File "/home/xgrdscpi/virtualenv/api.lulucollection-52.digitaltek.co.in/3.8/lib/python3.8/site-packages/django/conf/__init__.py", line 89, in _setup
    self._wrapped = Settings(settings_module)
  File "/home/xgrdscpi/virtualenv/api.lulucollection-52.digitaltek.co.in/3.8/lib/python3.8/site-packages/django/conf/__init__.py", line 217, in __init__
    mod = importlib.import_module(self.SETTINGS_MODULE)
  File "/opt/alt/python38/lib64/python3.8/importlib/__init__.py", line 127, in import_module
    return _bootstrap._gcd_import(name[level:], package, level)
  File "/home/xgrdscpi/api.lulucollection-52.digitaltek.co.in/backend/settings.py", line 26, in <module>
    SECRET_KEY = config('SECRET_KEY')
  File "/home/xgrdscpi/virtualenv/api.lulucollection-52.digitaltek.co.in/3.8/lib/python3.8/site-packages/decouple.py", line 248, in __call__
    return self.config(*args, **kwargs)
  File "/home/xgrdscpi/virtualenv/api.lulucollection-52.digitaltek.co.in/3.8/lib/python3.8/site-packages/decouple.py", line 107, in __call__
    return self.get(*args, **kwargs)
  File "/home/xgrdscpi/virtualenv/api.lulucollection-52.digitaltek.co.in/3.8/lib/python3.8/site-packages/decouple.py", line 92, in get
    raise UndefinedValueError('{} not found. Declare it as envvar or define a default value.'.format(option))
decouple.UndefinedValueError: SECRET_KEY not found. Declare it as envvar or define a default value.
[UID:4986][2831005] Child process with pid: 2831087 was killed by signal: 15, core dump: 0
Error blacklisting refresh token: Token is blacklisted
[ERROR] [UID:4986][3114331] wsgiAppHandler pApp->start_response() return NULL.
Traceback (most recent call last):
  File "/home/xgrdscpi/virtualenv/api.lulucollection-52.digitaltek.co.in/3.8/lib/python3.8/site-packages/django/core/handlers/exception.py", line 55, in inner
    response = get_response(request)
  File "/home/xgrdscpi/virtualenv/api.lulucollection-52.digitaltek.co.in/3.8/lib/python3.8/site-packages/django/core/handlers/base.py", line 181, in _get_response
    callback, callback_args, callback_kwargs = self.resolve_request(request)
  File "/home/xgrdscpi/virtualenv/api.lulucollection-52.digitaltek.co.in/3.8/lib/python3.8/site-packages/django/core/handlers/base.py", line 313, in resolve_request
    resolver_match = resolver.resolve(request.path_info)
  File "/home/xgrdscpi/virtualenv/api.lulucollection-52.digitaltek.co.in/3.8/lib/python3.8/site-packages/django/urls/resolvers.py", line 663, in resolve
    for pattern in self.url_patterns:
  File "/home/xgrdscpi/virtualenv/api.lulucollection-52.digitaltek.co.in/3.8/lib/python3.8/site-packages/django/utils/functional.py", line 57, in __get__
    res = instance.__dict__[self.name] = self.func(instance)
  File "/home/xgrdscpi/virtualenv/api.lulucollection-52.digitaltek.co.in/3.8/lib/python3.8/site-packages/django/urls/resolvers.py", line 715, in url_patterns
    patterns = getattr(self.urlconf_module, "urlpatterns", self.urlconf_module)
  File "/home/xgrdscpi/virtualenv/api.lulucollection-52.digitaltek.co.in/3.8/lib/python3.8/site-packages/django/utils/functional.py", line 57, in __get__
    res = instance.__dict__[self.name] = self.func(instance)
  File "/home/xgrdscpi/virtualenv/api.lulucollection-52.digitaltek.co.in/3.8/lib/python3.8/site-packages/django/urls/resolvers.py", line 708, in urlconf_module
    return import_module(self.urlconf_name)
  File "/opt/alt/python38/lib64/python3.8/importlib/__init__.py", line 127, in import_module
    return _bootstrap._gcd_import(name[level:], package, level)
  File "<frozen importlib._bootstrap>", line 1014, in _gcd_import
  File "<frozen importlib._bootstrap>", line 991, in _find_and_load
  File "<frozen importlib._bootstrap>", line 975, in _find_and_load_unlocked
  File "<frozen importlib._bootstrap>", line 671, in _load_unlocked
  File "<frozen importlib._bootstrap_external>", line 843, in exec_module
  File "<frozen importlib._bootstrap>", line 219, in _call_with_frames_removed
  File "/home/xgrdscpi/api.lulucollection-52.digitaltek.co.in/backend/urls.py", line 33, in <module>
    path('api/', include('dashboard.urls')),
  File "/home/xgrdscpi/virtualenv/api.lulucollection-52.digitaltek.co.in/3.8/lib/python3.8/site-packages/django/urls/conf.py", line 38, in include
    urlconf_module = import_module(urlconf_module)
  File "/opt/alt/python38/lib64/python3.8/importlib/__init__.py", line 127, in import_module
    return _bootstrap._gcd_import(name[level:], package, level)
  File "<frozen importlib._bootstrap>", line 1014, in _gcd_import
  File "<frozen importlib._bootstrap>", line 991, in _find_and_load
  File "<frozen importlib._bootstrap>", line 975, in _find_and_load_unlocked
  File "<frozen importlib._bootstrap>", line 671, in _load_unlocked
  File "<frozen importlib._bootstrap_external>", line 843, in exec_module
  File "<frozen importlib._bootstrap>", line 219, in _call_with_frames_removed
  File "/home/xgrdscpi/api.lulucollection-52.digitaltek.co.in/dashboard/urls.py", line 4, in <module>
    from dashboard.views import (  
  File "/home/xgrdscpi/api.lulucollection-52.digitaltek.co.in/dashboard/views.py", line 7, in <module>
    from dashboard.serializers import (CategorySerializer, ContactUsSerializer,AboutUsSerializer,
ImportError: cannot import name 'AboutUsSerializer' from 'dashboard.serializers' (/home/xgrdscpi/api.lulucollection-52.digitaltek.co.in/dashboard/serializers.py)

During handling of the above exception, another exception occurred:

Traceback (most recent call last):
  File "/home/xgrdscpi/virtualenv/api.lulucollection-52.digitaltek.co.in/3.8/lib/python3.8/site-packages/django/core/handlers/exception.py", line 55, in inner
    response = get_response(request)
  File "/home/xgrdscpi/virtualenv/api.lulucollection-52.digitaltek.co.in/3.8/lib/python3.8/site-packages/django/utils/deprecation.py", line 134, in __call__
    response = response or self.get_response(request)
  File "/home/xgrdscpi/virtualenv/api.lulucollection-52.digitaltek.co.in/3.8/lib/python3.8/site-packages/django/core/handlers/exception.py", line 57, in inner
    response = response_for_exception(request, exc)
  File "/home/xgrdscpi/virtualenv/api.lulucollection-52.digitaltek.co.in/3.8/lib/python3.8/site-packages/django/core/handlers/exception.py", line 140, in response_for_exception
    response = handle_uncaught_exception(
  File "/home/xgrdscpi/virtualenv/api.lulucollection-52.digitaltek.co.in/3.8/lib/python3.8/site-packages/django/core/handlers/exception.py", line 184, in handle_uncaught_exception
    callback = resolver.resolve_error_handler(500)
  File "/home/xgrdscpi/virtualenv/api.lulucollection-52.digitaltek.co.in/3.8/lib/python3.8/site-packages/django/urls/resolvers.py", line 729, in resolve_error_handler
    callback = getattr(self.urlconf_module, "handler%s" % view_type, None)
  File "/home/xgrdscpi/virtualenv/api.lulucollection-52.digitaltek.co.in/3.8/lib/python3.8/site-packages/django/utils/functional.py", line 57, in __get__
    res = instance.__dict__[self.name] = self.func(instance)
  File "/home/xgrdscpi/virtualenv/api.lulucollection-52.digitaltek.co.in/3.8/lib/python3.8/site-packages/django/urls/resolvers.py", line 708, in urlconf_module
    return import_module(self.urlconf_name)
  File "/opt/alt/python38/lib64/python3.8/importlib/__init__.py", line 127, in import_module
    return _bootstrap._gcd_import(name[level:], package, level)
  File "<frozen importlib._bootstrap>", line 1014, in _gcd_import
  File "<frozen importlib._bootstrap>", line 991, in _find_and_load
  File "<frozen importlib._bootstrap>", line 975, in _find_and_load_unlocked
  File "<frozen importlib._bootstrap>", line 671, in _load_unlocked
  File "<frozen importlib._bootstrap_external>", line 843, in exec_module
  File "<frozen importlib._bootstrap>", line 219, in _call_with_frames_removed
  File "/home/xgrdscpi/api.lulucollection-52.digitaltek.co.in/backend/urls.py", line 33, in <module>
    path('api/', include('dashboard.urls')),
  File "/home/xgrdscpi/virtualenv/api.lulucollection-52.digitaltek.co.in/3.8/lib/python3.8/site-packages/django/urls/conf.py", line 38, in include
    urlconf_module = import_module(urlconf_module)
  File "/opt/alt/python38/lib64/python3.8/importlib/__init__.py", line 127, in import_module
    return _bootstrap._gcd_import(name[level:], package, level)
  File "<frozen importlib._bootstrap>", line 1014, in _gcd_import
  File "<frozen importlib._bootstrap>", line 991, in _find_and_load
  File "<frozen importlib._bootstrap>", line 975, in _find_and_load_unlocked
  File "<frozen importlib._bootstrap>", line 671, in _load_unlocked
  File "<frozen importlib._bootstrap_external>", line 843, in exec_module
  File "<frozen importlib._bootstrap>", line 219, in _call_with_frames_removed
  File "/home/xgrdscpi/api.lulucollection-52.digitaltek.co.in/dashboard/urls.py", line 4, in <module>
    from dashboard.views import (  
  File "/home/xgrdscpi/api.lulucollection-52.digitaltek.co.in/dashboard/views.py", line 7, in <module>
    from dashboard.serializers import (CategorySerializer, ContactUsSerializer,AboutUsSerializer,
ImportError: cannot import name 'AboutUsSerializer' from 'dashboard.serializers' (/home/xgrdscpi/api.lulucollection-52.digitaltek.co.in/dashboard/serializers.py)

During handling of the above exception, another exception occurred:

Traceback (most recent call last):
  File "/home/xgrdscpi/virtualenv/api.lulucollection-52.digitaltek.co.in/3.8/lib/python3.8/site-packages/django/core/handlers/exception.py", line 55, in inner
    response = get_response(request)
  File "/home/xgrdscpi/virtualenv/api.lulucollection-52.digitaltek.co.in/3.8/lib/python3.8/site-packages/django/utils/deprecation.py", line 134, in __call__
    response = response or self.get_response(request)
[ERROR] [UID:4986][3114343] wsgiAppHandler pApp->start_response() return NULL.
  File "/home/xgrdscpi/virtualenv/api.lulucollection-52.digitaltek.co.in/3.8/lib/python3.8/site-packages/django/core/handlers/exception.py", line 57, in inner
    response = response_for_exception(request, exc)
  File "/home/xgrdscpi/virtualenv/api.lulucollection-52.digitaltek.co.in/3.8/lib/python3.8/site-packages/django/core/handlers/exception.py", line 140, in response_for_exception
    response = handle_uncaught_exception(
  File "/home/xgrdscpi/virtualenv/api.lulucollection-52.digitaltek.co.in/3.8/lib/python3.8/site-packages/django/core/handlers/exception.py", line 184, in handle_uncaught_exception
    callback = resolver.resolve_error_handler(500)
  File "/home/xgrdscpi/virtualenv/api.lulucollection-52.digitaltek.co.in/3.8/lib/python3.8/site-packages/django/urls/resolvers.py", line 729, in resolve_error_handler
    callback = getattr(self.urlconf_module, "handler%s" % view_type, None)
  File "/home/xgrdscpi/virtualenv/api.lulucollection-52.digitaltek.co.in/3.8/lib/python3.8/site-packages/django/utils/functional.py", line 57, in __get__
    res = instance.__dict__[self.name] = self.func(instance)
  File "/home/xgrdscpi/virtualenv/api.lulucollection-52.digitaltek.co.in/3.8/lib/python3.8/site-packages/django/urls/resolvers.py", line 708, in urlconf_module
    return import_module(self.urlconf_name)
  File "/opt/alt/python38/lib64/python3.8/importlib/__init__.py", line 127, in import_module
    return _bootstrap._gcd_import(name[level:], package, level)
  File "<frozen importlib._bootstrap>", line 1014, in _gcd_import
  File "<frozen importlib._bootstrap>", line 991, in _find_and_load
  File "<frozen importlib._bootstrap>", line 975, in _find_and_load_unlocked
  File "<frozen importlib._bootstrap>", line 671, in _load_unlocked
  File "<frozen importlib._bootstrap_external>", line 843, in exec_module
  File "<frozen importlib._bootstrap>", line 219, in _call_with_frames_removed
  File "/home/xgrdscpi/api.lulucollection-52.digitaltek.co.in/backend/urls.py", line 33, in <module>
    path('api/', include('dashboard.urls')),
  File "/home/xgrdscpi/virtualenv/api.lulucollection-52.digitaltek.co.in/3.8/lib/python3.8/site-packages/django/urls/conf.py", line 38, in include
    urlconf_module = import_module(urlconf_module)
  File "/opt/alt/python38/lib64/python3.8/importlib/__init__.py", line 127, in import_module
    return _bootstrap._gcd_import(name[level:], package, level)
  File "<frozen importlib._bootstrap>", line 1014, in _gcd_import
  File "<frozen importlib._bootstrap>", line 991, in _find_and_load
  File "<frozen importlib._bootstrap>", line 975, in _find_and_load_unlocked
  File "<frozen importlib._bootstrap>", line 671, in _load_unlocked
  File "<frozen importlib._bootstrap_external>", line 843, in exec_module
  File "<frozen importlib._bootstrap>", line 219, in _call_with_frames_removed
  File "/home/xgrdscpi/api.lulucollection-52.digitaltek.co.in/dashboard/urls.py", line 4, in <module>
    from dashboard.views import (  
  File "/home/xgrdscpi/api.lulucollection-52.digitaltek.co.in/dashboard/views.py", line 7, in <module>
    from dashboard.serializers import (CategorySerializer, ContactUsSerializer,AboutUsSerializer,
ImportError: cannot import name 'AboutUsSerializer' from 'dashboard.serializers' (/home/xgrdscpi/api.lulucollection-52.digitaltek.co.in/dashboard/serializers.py)

During handling of the above exception, another exception occurred:

Traceback (most recent call last):
  File "/home/xgrdscpi/virtualenv/api.lulucollection-52.digitaltek.co.in/3.8/lib/python3.8/site-packages/django/core/handlers/exception.py", line 55, in inner
    response = get_response(request)
  File "/home/xgrdscpi/virtualenv/api.lulucollection-52.digitaltek.co.in/3.8/lib/python3.8/site-packages/django/utils/deprecation.py", line 134, in __call__
    response = response or self.get_response(request)
  File "/home/xgrdscpi/virtualenv/api.lulucollection-52.digitaltek.co.in/3.8/lib/python3.8/site-packages/django/core/handlers/exception.py", line 57, in inner
    response = response_for_exception(request, exc)
  File "/home/xgrdscpi/virtualenv/api.lulucollection-52.digitaltek.co.in/3.8/lib/python3.8/site-packages/django/core/handlers/exception.py", line 140, in response_for_exception
    response = handle_uncaught_exception(
  File "/home/xgrdscpi/virtualenv/api.lulucollection-52.digitaltek.co.in/3.8/lib/python3.8/site-packages/django/core/handlers/exception.py", line 184, in handle_uncaught_exception
    callback = resolver.resolve_error_handler(500)
  File "/home/xgrdscpi/virtualenv/api.lulucollection-52.digitaltek.co.in/3.8/lib/python3.8/site-packages/django/urls/resolvers.py", line 729, in resolve_error_handler
    callback = getattr(self.urlconf_module, "handler%s" % view_type, None)
  File "/home/xgrdscpi/virtualenv/api.lulucollection-52.digitaltek.co.in/3.8/lib/python3.8/site-packages/django/utils/functional.py", line 57, in __get__
    res = instance.__dict__[self.name] = self.func(instance)
  File "/home/xgrdscpi/virtualenv/api.lulucollection-52.digitaltek.co.in/3.8/lib/python3.8/site-packages/django/urls/resolvers.py", line 708, in urlconf_module
    return import_module(self.urlconf_name)
  File "/opt/alt/python38/lib64/python3.8/importlib/__init__.py", line 127, in import_module
    return _bootstrap._gcd_import(name[level:], package, level)
  File "<frozen importlib._bootstrap>", line 1014, in _gcd_import
  File "<frozen importlib._bootstrap>", line 991, in _find_and_load
  File "<frozen importlib._bootstrap>", line 975, in _find_and_load_unlocked
  File "<frozen importlib._bootstrap>", line 671, in _load_unlocked
  File "<frozen importlib._bootstrap_external>", line 843, in exec_module
  File "<frozen importlib._bootstrap>", line 219, in _call_with_frames_removed
  File "/home/xgrdscpi/api.lulucollection-52.digitaltek.co.in/backend/urls.py", line 33, in <module>
    path('api/', include('dashboard.urls')),
  File "/home/xgrdscpi/virtualenv/api.lulucollection-52.digitaltek.co.in/3.8/lib/python3.8/site-packages/django/urls/conf.py", line 38, in include
    urlconf_module = import_module(urlconf_module)
  File "/opt/alt/python38/lib64/python3.8/importlib/__init__.py", line 127, in import_module
    return _bootstrap._gcd_import(name[level:], package, level)
  File "<frozen importlib._bootstrap>", line 1014, in _gcd_import
  File "<frozen importlib._bootstrap>", line 991, in _find_and_load
  File "<frozen importlib._bootstrap>", line 975, in _find_and_load_unlocked
  File "<frozen importlib._bootstrap>", line 671, in _load_unlocked
  File "<frozen importlib._bootstrap_external>", line 843, in exec_module
  File "<frozen importlib._bootstrap>", line 219, in _call_with_frames_removed
  File "/home/xgrdscpi/api.lulucollection-52.digitaltek.co.in/dashboard/urls.py", line 4, in <module>
    from dashboard.views import (  
  File "/home/xgrdscpi/api.lulucollection-52.digitaltek.co.in/dashboard/views.py", line 7, in <module>
    from dashboard.serializers import (CategorySerializer, ContactUsSerializer,AboutUsSerializer,
ImportError: cannot import name 'AboutUsSerializer' from 'dashboard.serializers' (/home/xgrdscpi/api.lulucollection-52.digitaltek.co.in/dashboard/serializers.py)

During handling of the above exception, another exception occurred:

Traceback (most recent call last):
  File "/home/xgrdscpi/virtualenv/api.lulucollection-52.digitaltek.co.in/3.8/lib/python3.8/site-packages/django/core/handlers/exception.py", line 55, in inner
    response = get_response(request)
  File "/home/xgrdscpi/virtualenv/api.lulucollection-52.digitaltek.co.in/3.8/lib/python3.8/site-packages/django/utils/deprecation.py", line 134, in __call__
    response = response or self.get_response(request)
  File "/home/xgrdscpi/virtualenv/api.lulucollection-52.digitaltek.co.in/3.8/lib/python3.8/site-packages/django/core/handlers/exception.py", line 57, in inner
    response = response_for_exception(request, exc)
  File "/home/xgrdscpi/virtualenv/api.lulucollection-52.digitaltek.co.in/3.8/lib/python3.8/site-packages/django/core/handlers/exception.py", line 140, in response_for_exception
    response = handle_uncaught_exception(
Traceback (most recent call last):
  File "/home/xgrdscpi/virtualenv/api.lulucollection-52.digitaltek.co.in/3.8/lib/python3.8/site-packages/django/core/handlers/exception.py", line 55, in inner
    response = get_response(request)
  File "/home/xgrdscpi/virtualenv/api.lulucollection-52.digitaltek.co.in/3.8/lib/python3.8/site-packages/django/core/handlers/base.py", line 181, in _get_response
    callback, callback_args, callback_kwargs = self.resolve_request(request)
  File "/home/xgrdscpi/virtualenv/api.lulucollection-52.digitaltek.co.in/3.8/lib/python3.8/site-packages/django/core/handlers/base.py", line 313, in resolve_request
    resolver_match = resolver.resolve(request.path_info)
  File "/home/xgrdscpi/virtualenv/api.lulucollection-52.digitaltek.co.in/3.8/lib/python3.8/site-packages/django/urls/resolvers.py", line 663, in resolve
    for pattern in self.url_patterns:
  File "/home/xgrdscpi/virtualenv/api.lulucollection-52.digitaltek.co.in/3.8/lib/python3.8/site-packages/django/utils/functional.py", line 57, in __get__
    res = instance.__dict__[self.name] = self.func(instance)
  File "/home/xgrdscpi/virtualenv/api.lulucollection-52.digitaltek.co.in/3.8/lib/python3.8/site-packages/django/urls/resolvers.py", line 715, in url_patterns
    patterns = getattr(self.urlconf_module, "urlpatterns", self.urlconf_module)
  File "/home/xgrdscpi/virtualenv/api.lulucollection-52.digitaltek.co.in/3.8/lib/python3.8/site-packages/django/utils/functional.py", line 57, in __get__
    res = instance.__dict__[self.name] = self.func(instance)
  File "/home/xgrdscpi/virtualenv/api.lulucollection-52.digitaltek.co.in/3.8/lib/python3.8/site-packages/django/urls/resolvers.py", line 708, in urlconf_module
    return import_module(self.urlconf_name)
  File "/opt/alt/python38/lib64/python3.8/importlib/__init__.py", line 127, in import_module
    return _bootstrap._gcd_import(name[level:], package, level)
  File "<frozen importlib._bootstrap>", line 1014, in _gcd_import
  File "<frozen importlib._bootstrap>", line 991, in _find_and_load
  File "<frozen importlib._bootstrap>", line 975, in _find_and_load_unlocked
  File "<frozen importlib._bootstrap>", line 671, in _load_unlocked
  File "<frozen importlib._bootstrap_external>", line 843, in exec_module
  File "<frozen importlib._bootstrap>", line 219, in _call_with_frames_removed
  File "/home/xgrdscpi/api.lulucollection-52.digitaltek.co.in/backend/urls.py", line 33, in <module>
    path('api/', include('dashboard.urls')),
  File "/home/xgrdscpi/virtualenv/api.lulucollection-52.digitaltek.co.in/3.8/lib/python3.8/site-packages/django/urls/conf.py", line 38, in include
    urlconf_module = import_module(urlconf_module)
  File "/opt/alt/python38/lib64/python3.8/importlib/__init__.py", line 127, in import_module
    return _bootstrap._gcd_import(name[level:], package, level)
  File "<frozen importlib._bootstrap>", line 1014, in _gcd_import
  File "<frozen importlib._bootstrap>", line 991, in _find_and_load
  File "<frozen importlib._bootstrap>", line 975, in _find_and_load_unlocked
  File "<frozen importlib._bootstrap>", line 671, in _load_unlocked
  File "<frozen importlib._bootstrap_external>", line 843, in exec_module
  File "<frozen importlib._bootstrap>", line 219, in _call_with_frames_removed
  File "/home/xgrdscpi/api.lulucollection-52.digitaltek.co.in/dashboard/urls.py", line 4, in <module>
    from dashboard.views import (  
  File "/home/xgrdscpi/api.lulucollection-52.digitaltek.co.in/dashboard/views.py", line 7, in <module>
    from dashboard.serializers import (CategorySerializer, ContactUsSerializer,AboutUsSerializer,
ImportError: cannot import name 'AboutUsSerializer' from 'dashboard.serializers' (/home/xgrdscpi/api.lulucollection-52.digitaltek.co.in/dashboard/serializers.py)

During handling of the above exception, another exception occurred:

Traceback (most recent call last):
  File "/home/xgrdscpi/virtualenv/api.lulucollection-52.digitaltek.co.in/3.8/lib/python3.8/site-packages/django/core/handlers/exception.py", line 55, in inner
    response = get_response(request)
  File "/home/xgrdscpi/virtualenv/api.lulucollection-52.digitaltek.co.in/3.8/lib/python3.8/site-packages/django/utils/deprecation.py", line 134, in __call__
    response = response or self.get_response(request)
  File "/home/xgrdscpi/virtualenv/api.lulucollection-52.digitaltek.co.in/3.8/lib/python3.8/site-packages/django/core/handlers/exception.py", line 57, in inner
    response = response_for_exception(request, exc)
  File "/home/xgrdscpi/virtualenv/api.lulucollection-52.digitaltek.co.in/3.8/lib/python3.8/site-packages/django/core/handlers/exception.py", line 140, in response_for_exception
    response = handle_uncaught_exception(
  File "/home/xgrdscpi/virtualenv/api.lulucollection-52.digitaltek.co.in/3.8/lib/python3.8/site-packages/django/core/handlers/exception.py", line 184, in handle_uncaught_exception
    callback = resolver.resolve_error_handler(500)
  File "/home/xgrdscpi/virtualenv/api.lulucollection-52.digitaltek.co.in/3.8/lib/python3.8/site-packages/django/urls/resolvers.py", line 729, in resolve_error_handler
    callback = getattr(self.urlconf_module, "handler%s" % view_type, None)
  File "/home/xgrdscpi/virtualenv/api.lulucollection-52.digitaltek.co.in/3.8/lib/python3.8/site-packages/django/utils/functional.py", line 57, in __get__
    res = instance.__dict__[self.name] = self.func(instance)
  File "/home/xgrdscpi/virtualenv/api.lulucollection-52.digitaltek.co.in/3.8/lib/python3.8/site-packages/django/urls/resolvers.py", line 708, in urlconf_module
    return import_module(self.urlconf_name)
  File "/opt/alt/python38/lib64/python3.8/importlib/__init__.py", line 127, in import_module
    return _bootstrap._gcd_import(name[level:], package, level)
  File "<frozen importlib._bootstrap>", line 1014, in _gcd_import
  File "<frozen importlib._bootstrap>", line 991, in _find_and_load
  File "<frozen importlib._bootstrap>", line 975, in _find_and_load_unlocked
  File "<frozen importlib._bootstrap>", line 671, in _load_unlocked
  File "<frozen importlib._bootstrap_external>", line 843, in exec_module
  File "<frozen importlib._bootstrap>", line 219, in _call_with_frames_removed
  File "/home/xgrdscpi/api.lulucollection-52.digitaltek.co.in/backend/urls.py", line 33, in <module>
    path('api/', include('dashboard.urls')),
  File "/home/xgrdscpi/virtualenv/api.lulucollection-52.digitaltek.co.in/3.8/lib/python3.8/site-packages/django/urls/conf.py", line 38, in include
    urlconf_module = import_module(urlconf_module)
  File "/opt/alt/python38/lib64/python3.8/importlib/__init__.py", line 127, in import_module
    return _bootstrap._gcd_import(name[level:], package, level)
  File "<frozen importlib._bootstrap>", line 1014, in _gcd_import
  File "<frozen importlib._bootstrap>", line 991, in _find_and_load
  File "<frozen importlib._bootstrap>", line 975, in _find_and_load_unlocked
  File "<frozen importlib._bootstrap>", line 671, in _load_unlocked
  File "<frozen importlib._bootstrap_external>", line 843, in exec_module
  File "<frozen importlib._bootstrap>", line 219, in _call_with_frames_removed
  File "/home/xgrdscpi/api.lulucollection-52.digitaltek.co.in/dashboard/urls.py", line 4, in <module>
    from dashboard.views import (  
  File "/home/xgrdscpi/api.lulucollection-52.digitaltek.co.in/dashboard/views.py", line 7, in <module>
    from dashboard.serializers import (CategorySerializer, ContactUsSerializer,AboutUsSerializer,
ImportError: cannot import name 'AboutUsSerializer' from 'dashboard.serializers' (/home/xgrdscpi/api.lulucollection-52.digitaltek.co.in/dashboard/serializers.py)

During handling of the above exception, another exception occurred:

Traceback (most recent call last):
  File "/home/xgrdscpi/virtualenv/api.lulucollection-52.digitaltek.co.in/3.8/lib/python3.8/site-packages/django/core/handlers/exception.py", line 55, in inner
    response = get_response(request)
  File "/home/xgrdscpi/virtualenv/api.lulucollection-52.digitaltek.co.in/3.8/lib/python3.8/site-packages/django/utils/deprecation.py", line 134, in __call__
    response = response or self.get_response(request)
  File "/home/xgrdscpi/virtualenv/api.lulucollection-52.digitaltek.co.in/3.8/lib/python3.8/site-packages/django/core/handlers/exception.py", line 184, in handle_uncaught_exception
    callback = resolver.resolve_error_handler(500)
  File "/home/xgrdscpi/virtualenv/api.lulucollection-52.digitaltek.co.in/3.8/lib/python3.8/site-packages/django/urls/resolvers.py", line 729, in resolve_error_handler
    callback = getattr(self.urlconf_module, "handler%s" % view_type, None)
  File "/home/xgrdscpi/virtualenv/api.lulucollection-52.digitaltek.co.in/3.8/lib/python3.8/site-packages/django/utils/functional.py", line 57, in __get__
    res = instance.__dict__[self.name] = self.func(instance)
  File "/home/xgrdscpi/virtualenv/api.lulucollection-52.digitaltek.co.in/3.8/lib/python3.8/site-packages/django/urls/resolvers.py", line 708, in urlconf_module
    return import_module(self.urlconf_name)
  File "/opt/alt/python38/lib64/python3.8/importlib/__init__.py", line 127, in import_module
    return _bootstrap._gcd_import(name[level:], package, level)
  File "<frozen importlib._bootstrap>", line 1014, in _gcd_import
  File "<frozen importlib._bootstrap>", line 991, in _find_and_load
  File "<frozen importlib._bootstrap>", line 975, in _find_and_load_unlocked
  File "<frozen importlib._bootstrap>", line 671, in _load_unlocked
  File "<frozen importlib._bootstrap_external>", line 843, in exec_module
  File "<frozen importlib._bootstrap>", line 219, in _call_with_frames_removed
  File "/home/xgrdscpi/api.lulucollection-52.digitaltek.co.in/backend/urls.py", line 33, in <module>
    path('api/', include('dashboard.urls')),
  File "/home/xgrdscpi/virtualenv/api.lulucollection-52.digitaltek.co.in/3.8/lib/python3.8/site-packages/django/urls/conf.py", line 38, in include
    urlconf_module = import_module(urlconf_module)
  File "/opt/alt/python38/lib64/python3.8/importlib/__init__.py", line 127, in import_module
    return _bootstrap._gcd_import(name[level:], package, level)
  File "<frozen importlib._bootstrap>", line 1014, in _gcd_import
  File "<frozen importlib._bootstrap>", line 991, in _find_and_load
  File "<frozen importlib._bootstrap>", line 975, in _find_and_load_unlocked
  File "<frozen importlib._bootstrap>", line 671, in _load_unlocked
  File "<frozen importlib._bootstrap_external>", line 843, in exec_module
  File "<frozen importlib._bootstrap>", line 219, in _call_with_frames_removed
  File "/home/xgrdscpi/api.lulucollection-52.digitaltek.co.in/dashboard/urls.py", line 4, in <module>
    from dashboard.views import (  
  File "/home/xgrdscpi/api.lulucollection-52.digitaltek.co.in/dashboard/views.py", line 7, in <module>
    from dashboard.serializers import (CategorySerializer, ContactUsSerializer,AboutUsSerializer,
ImportError: cannot import name 'AboutUsSerializer' from 'dashboard.serializers' (/home/xgrdscpi/api.lulucollection-52.digitaltek.co.in/dashboard/serializers.py)

During handling of the above exception, another exception occurred:

Traceback (most recent call last):
  File "/home/xgrdscpi/virtualenv/api.lulucollection-52.digitaltek.co.in/3.8/lib/python3.8/site-packages/django/core/handlers/exception.py", line 55, in inner
    response = get_response(request)
  File "/home/xgrdscpi/virtualenv/api.lulucollection-52.digitaltek.co.in/3.8/lib/python3.8/site-packages/django/utils/deprecation.py", line 134, in __call__
    response = response or self.get_response(request)
  File "/home/xgrdscpi/virtualenv/api.lulucollection-52.digitaltek.co.in/3.8/lib/python3.8/site-packages/django/core/handlers/exception.py", line 57, in inner
    response = response_for_exception(request, exc)
  File "/home/xgrdscpi/virtualenv/api.lulucollection-52.digitaltek.co.in/3.8/lib/python3.8/site-packages/django/core/handlers/exception.py", line 140, in response_for_exception
    response = handle_uncaught_exception(
  File "/home/xgrdscpi/virtualenv/api.lulucollection-52.digitaltek.co.in/3.8/lib/python3.8/site-packages/django/core/handlers/exception.py", line 184, in handle_uncaught_exception
    callback = resolver.resolve_error_handler(500)
  File "/home/xgrdscpi/virtualenv/api.lulucollection-52.digitaltek.co.in/3.8/lib/python3.8/site-packages/django/urls/resolvers.py", line 729, in resolve_error_handler
    callback = getattr(self.urlconf_module, "handler%s" % view_type, None)
  File "/home/xgrdscpi/virtualenv/api.lulucollection-52.digitaltek.co.in/3.8/lib/python3.8/site-packages/django/utils/functional.py", line 57, in __get__
    res = instance.__dict__[self.name] = self.func(instance)
  File "/home/xgrdscpi/virtualenv/api.lulucollection-52.digitaltek.co.in/3.8/lib/python3.8/site-packages/django/urls/resolvers.py", line 708, in urlconf_module
    return import_module(self.urlconf_name)
  File "/opt/alt/python38/lib64/python3.8/importlib/__init__.py", line 127, in import_module
    return _bootstrap._gcd_import(name[level:], package, level)
  File "<frozen importlib._bootstrap>", line 1014, in _gcd_import
  File "<frozen importlib._bootstrap>", line 991, in _find_and_load
  File "<frozen importlib._bootstrap>", line 975, in _find_and_load_unlocked
  File "<frozen importlib._bootstrap>", line 671, in _load_unlocked
  File "<frozen importlib._bootstrap_external>", line 843, in exec_module
  File "<frozen importlib._bootstrap>", line 219, in _call_with_frames_removed
  File "/home/xgrdscpi/api.lulucollection-52.digitaltek.co.in/backend/urls.py", line 33, in <module>
    path('api/', include('dashboard.urls')),
  File "/home/xgrdscpi/virtualenv/api.lulucollection-52.digitaltek.co.in/3.8/lib/python3.8/site-packages/django/urls/conf.py", line 38, in include
    urlconf_module = import_module(urlconf_module)
  File "/opt/alt/python38/lib64/python3.8/importlib/__init__.py", line 127, in import_module
    return _bootstrap._gcd_import(name[level:], package, level)
  File "<frozen importlib._bootstrap>", line 1014, in _gcd_import
  File "<frozen importlib._bootstrap>", line 991, in _find_and_load
  File "<frozen importlib._bootstrap>", line 975, in _find_and_load_unlocked
  File "<frozen importlib._bootstrap>", line 671, in _load_unlocked
  File "<frozen importlib._bootstrap_external>", line 843, in exec_module
  File "<frozen importlib._bootstrap>", line 219, in _call_with_frames_removed
  File "/home/xgrdscpi/api.lulucollection-52.digitaltek.co.in/dashboard/urls.py", line 4, in <module>
    from dashboard.views import (  
  File "/home/xgrdscpi/api.lulucollection-52.digitaltek.co.in/dashboard/views.py", line 7, in <module>
    from dashboard.serializers import (CategorySerializer, ContactUsSerializer,AboutUsSerializer,
ImportError: cannot import name 'AboutUsSerializer' from 'dashboard.serializers' (/home/xgrdscpi/api.lulucollection-52.digitaltek.co.in/dashboard/serializers.py)

During handling of the above exception, another exception occurred:

Traceback (most recent call last):
  File "/home/xgrdscpi/virtualenv/api.lulucollection-52.digitaltek.co.in/3.8/lib/python3.8/site-packages/django/core/handlers/exception.py", line 55, in inner
    response = get_response(request)
  File "/home/xgrdscpi/virtualenv/api.lulucollection-52.digitaltek.co.in/3.8/lib/python3.8/site-packages/corsheaders/middleware.py", line 56, in __call__
    result = self.get_response(request)
  File "/home/xgrdscpi/virtualenv/api.lulucollection-52.digitaltek.co.in/3.8/lib/python3.8/site-packages/django/core/handlers/exception.py", line 57, in inner
    response = response_for_exception(request, exc)
  File "/home/xgrdscpi/virtualenv/api.lulucollection-52.digitaltek.co.in/3.8/lib/python3.8/site-packages/django/core/handlers/exception.py", line 140, in response_for_exception
    response = handle_uncaught_exception(
  File "/home/xgrdscpi/virtualenv/api.lulucollection-52.digitaltek.co.in/3.8/lib/python3.8/site-packages/django/core/handlers/exception.py", line 184, in handle_uncaught_exception
    callback = resolver.resolve_error_handler(500)
  File "/home/xgrdscpi/virtualenv/api.lulucollection-52.digitaltek.co.in/3.8/lib/python3.8/site-packages/django/urls/resolvers.py", line 729, in resolve_error_handler
    callback = getattr(self.urlconf_module, "handler%s" % view_type, None)
  File "/home/xgrdscpi/virtualenv/api.lulucollection-52.digitaltek.co.in/3.8/lib/python3.8/site-packages/django/core/handlers/exception.py", line 57, in inner
    response = response_for_exception(request, exc)
  File "/home/xgrdscpi/virtualenv/api.lulucollection-52.digitaltek.co.in/3.8/lib/python3.8/site-packages/django/core/handlers/exception.py", line 140, in response_for_exception
    response = handle_uncaught_exception(
  File "/home/xgrdscpi/virtualenv/api.lulucollection-52.digitaltek.co.in/3.8/lib/python3.8/site-packages/django/core/handlers/exception.py", line 184, in handle_uncaught_exception
    callback = resolver.resolve_error_handler(500)
  File "/home/xgrdscpi/virtualenv/api.lulucollection-52.digitaltek.co.in/3.8/lib/python3.8/site-packages/django/urls/resolvers.py", line 729, in resolve_error_handler
    callback = getattr(self.urlconf_module, "handler%s" % view_type, None)
  File "/home/xgrdscpi/virtualenv/api.lulucollection-52.digitaltek.co.in/3.8/lib/python3.8/site-packages/django/utils/functional.py", line 57, in __get__
    res = instance.__dict__[self.name] = self.func(instance)
  File "/home/xgrdscpi/virtualenv/api.lulucollection-52.digitaltek.co.in/3.8/lib/python3.8/site-packages/django/urls/resolvers.py", line 708, in urlconf_module
    return import_module(self.urlconf_name)
  File "/opt/alt/python38/lib64/python3.8/importlib/__init__.py", line 127, in import_module
    return _bootstrap._gcd_import(name[level:], package, level)
  File "<frozen importlib._bootstrap>", line 1014, in _gcd_import
  File "<frozen importlib._bootstrap>", line 991, in _find_and_load
  File "<frozen importlib._bootstrap>", line 975, in _find_and_load_unlocked
  File "<frozen importlib._bootstrap>", line 671, in _load_unlocked
  File "<frozen importlib._bootstrap_external>", line 843, in exec_module
  File "<frozen importlib._bootstrap>", line 219, in _call_with_frames_removed
  File "/home/xgrdscpi/api.lulucollection-52.digitaltek.co.in/backend/urls.py", line 33, in <module>
    path('api/', include('dashboard.urls')),
  File "/home/xgrdscpi/virtualenv/api.lulucollection-52.digitaltek.co.in/3.8/lib/python3.8/site-packages/django/urls/conf.py", line 38, in include
    urlconf_module = import_module(urlconf_module)
  File "/opt/alt/python38/lib64/python3.8/importlib/__init__.py", line 127, in import_module
    return _bootstrap._gcd_import(name[level:], package, level)
  File "<frozen importlib._bootstrap>", line 1014, in _gcd_import
  File "<frozen importlib._bootstrap>", line 991, in _find_and_load
  File "<frozen importlib._bootstrap>", line 975, in _find_and_load_unlocked
  File "<frozen importlib._bootstrap>", line 671, in _load_unlocked
  File "<frozen importlib._bootstrap_external>", line 843, in exec_module
  File "<frozen importlib._bootstrap>", line 219, in _call_with_frames_removed
  File "/home/xgrdscpi/api.lulucollection-52.digitaltek.co.in/dashboard/urls.py", line 4, in <module>
    from dashboard.views import (  
  File "/home/xgrdscpi/api.lulucollection-52.digitaltek.co.in/dashboard/views.py", line 7, in <module>
    from dashboard.serializers import (CategorySerializer, ContactUsSerializer,AboutUsSerializer,
ImportError: cannot import name 'AboutUsSerializer' from 'dashboard.serializers' (/home/xgrdscpi/api.lulucollection-52.digitaltek.co.in/dashboard/serializers.py)

During handling of the above exception, another exception occurred:

Traceback (most recent call last):
  File "/home/xgrdscpi/virtualenv/api.lulucollection-52.digitaltek.co.in/3.8/lib/python3.8/site-packages/django/core/handlers/exception.py", line 55, in inner
    response = get_response(request)
  File "/home/xgrdscpi/virtualenv/api.lulucollection-52.digitaltek.co.in/3.8/lib/python3.8/site-packages/django/utils/deprecation.py", line 134, in __call__
    response = response or self.get_response(request)
  File "/home/xgrdscpi/virtualenv/api.lulucollection-52.digitaltek.co.in/3.8/lib/python3.8/site-packages/django/core/handlers/exception.py", line 57, in inner
    response = response_for_exception(request, exc)
  File "/home/xgrdscpi/virtualenv/api.lulucollection-52.digitaltek.co.in/3.8/lib/python3.8/site-packages/django/core/handlers/exception.py", line 140, in response_for_exception
    response = handle_uncaught_exception(
  File "/home/xgrdscpi/virtualenv/api.lulucollection-52.digitaltek.co.in/3.8/lib/python3.8/site-packages/django/core/handlers/exception.py", line 184, in handle_uncaught_exception
    callback = resolver.resolve_error_handler(500)
  File "/home/xgrdscpi/virtualenv/api.lulucollection-52.digitaltek.co.in/3.8/lib/python3.8/site-packages/django/urls/resolvers.py", line 729, in resolve_error_handler
    callback = getattr(self.urlconf_module, "handler%s" % view_type, None)
  File "/home/xgrdscpi/virtualenv/api.lulucollection-52.digitaltek.co.in/3.8/lib/python3.8/site-packages/django/utils/functional.py", line 57, in __get__
    res = instance.__dict__[self.name] = self.func(instance)
  File "/home/xgrdscpi/virtualenv/api.lulucollection-52.digitaltek.co.in/3.8/lib/python3.8/site-packages/django/urls/resolvers.py", line 708, in urlconf_module
    return import_module(self.urlconf_name)
  File "/opt/alt/python38/lib64/python3.8/importlib/__init__.py", line 127, in import_module
    return _bootstrap._gcd_import(name[level:], package, level)
  File "<frozen importlib._bootstrap>", line 1014, in _gcd_import
  File "<frozen importlib._bootstrap>", line 991, in _find_and_load
  File "<frozen importlib._bootstrap>", line 975, in _find_and_load_unlocked
  File "<frozen importlib._bootstrap>", line 671, in _load_unlocked
  File "<frozen importlib._bootstrap_external>", line 843, in exec_module
  File "<frozen importlib._bootstrap>", line 219, in _call_with_frames_removed
  File "/home/xgrdscpi/api.lulucollection-52.digitaltek.co.in/backend/urls.py", line 33, in <module>
    path('api/', include('dashboard.urls')),
  File "/home/xgrdscpi/virtualenv/api.lulucollection-52.digitaltek.co.in/3.8/lib/python3.8/site-packages/django/urls/conf.py", line 38, in include
    urlconf_module = import_module(urlconf_module)
  File "/opt/alt/python38/lib64/python3.8/importlib/__init__.py", line 127, in import_module
    return _bootstrap._gcd_import(name[level:], package, level)
  File "<frozen importlib._bootstrap>", line 1014, in _gcd_import
  File "<frozen importlib._bootstrap>", line 991, in _find_and_load
  File "<frozen importlib._bootstrap>", line 975, in _find_and_load_unlocked
  File "<frozen importlib._bootstrap>", line 671, in _load_unlocked
  File "<frozen importlib._bootstrap_external>", line 843, in exec_module
  File "<frozen importlib._bootstrap>", line 219, in _call_with_frames_removed
  File "/home/xgrdscpi/api.lulucollection-52.digitaltek.co.in/dashboard/urls.py", line 4, in <module>
    from dashboard.views import (  
  File "/home/xgrdscpi/api.lulucollection-52.digitaltek.co.in/dashboard/views.py", line 7, in <module>
    from dashboard.serializers import (CategorySerializer, ContactUsSerializer,AboutUsSerializer,
ImportError: cannot import name 'AboutUsSerializer' from 'dashboard.serializers' (/home/xgrdscpi/api.lulucollection-52.digitaltek.co.in/dashboard/serializers.py)

During handling of the above exception, another exception occurred:

Traceback (most recent call last):
  File "/home/xgrdscpi/virtualenv/api.lulucollection-52.digitaltek.co.in/3.8/lib/python3.8/site-packages/django/core/handlers/exception.py", line 55, in inner
    response = get_response(request)
  File "/home/xgrdscpi/virtualenv/api.lulucollection-52.digitaltek.co.in/3.8/lib/python3.8/site-packages/django/utils/deprecation.py", line 134, in __call__
    response = response or self.get_response(request)
  File "/home/xgrdscpi/virtualenv/api.lulucollection-52.digitaltek.co.in/3.8/lib/python3.8/site-packages/django/core/handlers/exception.py", line 57, in inner
    response = response_for_exception(request, exc)
  File "/home/xgrdscpi/virtualenv/api.lulucollection-52.digitaltek.co.in/3.8/lib/python3.8/site-packages/django/core/handlers/exception.py", line 140, in response_for_exception
    response = handle_uncaught_exception(
  File "/home/xgrdscpi/virtualenv/api.lulucollection-52.digitaltek.co.in/3.8/lib/python3.8/site-packages/django/utils/functional.py", line 57, in __get__
    res = instance.__dict__[self.name] = self.func(instance)
  File "/home/xgrdscpi/virtualenv/api.lulucollection-52.digitaltek.co.in/3.8/lib/python3.8/site-packages/django/urls/resolvers.py", line 708, in urlconf_module
    return import_module(self.urlconf_name)
  File "/opt/alt/python38/lib64/python3.8/importlib/__init__.py", line 127, in import_module
    return _bootstrap._gcd_import(name[level:], package, level)
  File "<frozen importlib._bootstrap>", line 1014, in _gcd_import
  File "<frozen importlib._bootstrap>", line 991, in _find_and_load
  File "<frozen importlib._bootstrap>", line 975, in _find_and_load_unlocked
  File "<frozen importlib._bootstrap>", line 671, in _load_unlocked
  File "<frozen importlib._bootstrap_external>", line 843, in exec_module
  File "<frozen importlib._bootstrap>", line 219, in _call_with_frames_removed
  File "/home/xgrdscpi/api.lulucollection-52.digitaltek.co.in/backend/urls.py", line 33, in <module>
    path('api/', include('dashboard.urls')),
  File "/home/xgrdscpi/virtualenv/api.lulucollection-52.digitaltek.co.in/3.8/lib/python3.8/site-packages/django/urls/conf.py", line 38, in include
    urlconf_module = import_module(urlconf_module)
  File "/opt/alt/python38/lib64/python3.8/importlib/__init__.py", line 127, in import_module
    return _bootstrap._gcd_import(name[level:], package, level)
  File "<frozen importlib._bootstrap>", line 1014, in _gcd_import
  File "<frozen importlib._bootstrap>", line 991, in _find_and_load
  File "<frozen importlib._bootstrap>", line 975, in _find_and_load_unlocked
  File "<frozen importlib._bootstrap>", line 671, in _load_unlocked
  File "<frozen importlib._bootstrap_external>", line 843, in exec_module
  File "<frozen importlib._bootstrap>", line 219, in _call_with_frames_removed
  File "/home/xgrdscpi/api.lulucollection-52.digitaltek.co.in/dashboard/urls.py", line 4, in <module>
    from dashboard.views import (  
  File "/home/xgrdscpi/api.lulucollection-52.digitaltek.co.in/dashboard/views.py", line 7, in <module>
    from dashboard.serializers import (CategorySerializer, ContactUsSerializer,AboutUsSerializer,
ImportError: cannot import name 'AboutUsSerializer' from 'dashboard.serializers' (/home/xgrdscpi/api.lulucollection-52.digitaltek.co.in/dashboard/serializers.py)

During handling of the above exception, another exception occurred:

Traceback (most recent call last):
  File "/home/xgrdscpi/virtualenv/api.lulucollection-52.digitaltek.co.in/3.8/lib/python3.8/site-packages/django/core/handlers/exception.py", line 55, in inner
    response = get_response(request)
  File "/home/xgrdscpi/virtualenv/api.lulucollection-52.digitaltek.co.in/3.8/lib/python3.8/site-packages/django/utils/deprecation.py", line 134, in __call__
    response = response or self.get_response(request)
  File "/home/xgrdscpi/virtualenv/api.lulucollection-52.digitaltek.co.in/3.8/lib/python3.8/site-packages/django/core/handlers/exception.py", line 57, in inner
    response = response_for_exception(request, exc)
  File "/home/xgrdscpi/virtualenv/api.lulucollection-52.digitaltek.co.in/3.8/lib/python3.8/site-packages/django/core/handlers/exception.py", line 140, in response_for_exception
    response = handle_uncaught_exception(
  File "/home/xgrdscpi/virtualenv/api.lulucollection-52.digitaltek.co.in/3.8/lib/python3.8/site-packages/django/core/handlers/exception.py", line 184, in handle_uncaught_exception
    callback = resolver.resolve_error_handler(500)
  File "/home/xgrdscpi/virtualenv/api.lulucollection-52.digitaltek.co.in/3.8/lib/python3.8/site-packages/django/urls/resolvers.py", line 729, in resolve_error_handler
    callback = getattr(self.urlconf_module, "handler%s" % view_type, None)
  File "/home/xgrdscpi/virtualenv/api.lulucollection-52.digitaltek.co.in/3.8/lib/python3.8/site-packages/django/utils/functional.py", line 57, in __get__
    res = instance.__dict__[self.name] = self.func(instance)
  File "/home/xgrdscpi/virtualenv/api.lulucollection-52.digitaltek.co.in/3.8/lib/python3.8/site-packages/django/urls/resolvers.py", line 708, in urlconf_module
    return import_module(self.urlconf_name)
  File "/opt/alt/python38/lib64/python3.8/importlib/__init__.py", line 127, in import_module
    return _bootstrap._gcd_import(name[level:], package, level)
  File "<frozen importlib._bootstrap>", line 1014, in _gcd_import
  File "<frozen importlib._bootstrap>", line 991, in _find_and_load
  File "<frozen importlib._bootstrap>", line 975, in _find_and_load_unlocked
  File "<frozen importlib._bootstrap>", line 671, in _load_unlocked
  File "<frozen importlib._bootstrap_external>", line 843, in exec_module
  File "<frozen importlib._bootstrap>", line 219, in _call_with_frames_removed
  File "/home/xgrdscpi/api.lulucollection-52.digitaltek.co.in/backend/urls.py", line 33, in <module>
    path('api/', include('dashboard.urls')),
  File "/home/xgrdscpi/virtualenv/api.lulucollection-52.digitaltek.co.in/3.8/lib/python3.8/site-packages/django/urls/conf.py", line 38, in include
    urlconf_module = import_module(urlconf_module)
  File "/opt/alt/python38/lib64/python3.8/importlib/__init__.py", line 127, in import_module
    return _bootstrap._gcd_import(name[level:], package, level)
  File "<frozen importlib._bootstrap>", line 1014, in _gcd_import
  File "<frozen importlib._bootstrap>", line 991, in _find_and_load
  File "<frozen importlib._bootstrap>", line 975, in _find_and_load_unlocked
  File "<frozen importlib._bootstrap>", line 671, in _load_unlocked
  File "<frozen importlib._bootstrap_external>", line 843, in exec_module
  File "<frozen importlib._bootstrap>", line 219, in _call_with_frames_removed
  File "/home/xgrdscpi/api.lulucollection-52.digitaltek.co.in/dashboard/urls.py", line 4, in <module>
    from dashboard.views import (  
  File "/home/xgrdscpi/api.lulucollection-52.digitaltek.co.in/dashboard/views.py", line 7, in <module>
    from dashboard.serializers import (CategorySerializer, ContactUsSerializer,AboutUsSerializer,
ImportError: cannot import name 'AboutUsSerializer' from 'dashboard.serializers' (/home/xgrdscpi/api.lulucollection-52.digitaltek.co.in/dashboard/serializers.py)

During handling of the above exception, another exception occurred:

Traceback (most recent call last):
  File "/home/xgrdscpi/virtualenv/api.lulucollection-52.digitaltek.co.in/3.8/lib/python3.8/site-packages/django/core/handlers/exception.py", line 55, in inner
    response = get_response(request)
  File "/home/xgrdscpi/virtualenv/api.lulucollection-52.digitaltek.co.in/3.8/lib/python3.8/site-packages/django/utils/deprecation.py", line 134, in __call__
    response = response or self.get_response(request)
  File "/home/xgrdscpi/virtualenv/api.lulucollection-52.digitaltek.co.in/3.8/lib/python3.8/site-packages/django/core/handlers/exception.py", line 57, in inner
    response = response_for_exception(request, exc)
  File "/home/xgrdscpi/virtualenv/api.lulucollection-52.digitaltek.co.in/3.8/lib/python3.8/site-packages/django/core/handlers/exception.py", line 140, in response_for_exception
    response = handle_uncaught_exception(
  File "/home/xgrdscpi/virtualenv/api.lulucollection-52.digitaltek.co.in/3.8/lib/python3.8/site-packages/django/core/handlers/exception.py", line 184, in handle_uncaught_exception
    callback = resolver.resolve_error_handler(500)
  File "/home/xgrdscpi/virtualenv/api.lulucollection-52.digitaltek.co.in/3.8/lib/python3.8/site-packages/django/urls/resolvers.py", line 729, in resolve_error_handler
    callback = getattr(self.urlconf_module, "handler%s" % view_type, None)
  File "/home/xgrdscpi/virtualenv/api.lulucollection-52.digitaltek.co.in/3.8/lib/python3.8/site-packages/django/utils/functional.py", line 57, in __get__
    res = instance.__dict__[self.name] = self.func(instance)
  File "/home/xgrdscpi/virtualenv/api.lulucollection-52.digitaltek.co.in/3.8/lib/python3.8/site-packages/django/urls/resolvers.py", line 708, in urlconf_module
    return import_module(self.urlconf_name)
  File "/home/xgrdscpi/virtualenv/api.lulucollection-52.digitaltek.co.in/3.8/lib/python3.8/site-packages/django/core/handlers/exception.py", line 184, in handle_uncaught_exception
    callback = resolver.resolve_error_handler(500)
  File "/home/xgrdscpi/virtualenv/api.lulucollection-52.digitaltek.co.in/3.8/lib/python3.8/site-packages/django/urls/resolvers.py", line 729, in resolve_error_handler
    callback = getattr(self.urlconf_module, "handler%s" % view_type, None)
  File "/home/xgrdscpi/virtualenv/api.lulucollection-52.digitaltek.co.in/3.8/lib/python3.8/site-packages/django/utils/functional.py", line 57, in __get__
    res = instance.__dict__[self.name] = self.func(instance)
  File "/home/xgrdscpi/virtualenv/api.lulucollection-52.digitaltek.co.in/3.8/lib/python3.8/site-packages/django/urls/resolvers.py", line 708, in urlconf_module
    return import_module(self.urlconf_name)
  File "/opt/alt/python38/lib64/python3.8/importlib/__init__.py", line 127, in import_module
    return _bootstrap._gcd_import(name[level:], package, level)
  File "<frozen importlib._bootstrap>", line 1014, in _gcd_import
  File "<frozen importlib._bootstrap>", line 991, in _find_and_load
  File "<frozen importlib._bootstrap>", line 975, in _find_and_load_unlocked
  File "<frozen importlib._bootstrap>", line 671, in _load_unlocked
  File "<frozen importlib._bootstrap_external>", line 843, in exec_module
  File "<frozen importlib._bootstrap>", line 219, in _call_with_frames_removed
  File "/home/xgrdscpi/api.lulucollection-52.digitaltek.co.in/backend/urls.py", line 33, in <module>
    path('api/', include('dashboard.urls')),
  File "/home/xgrdscpi/virtualenv/api.lulucollection-52.digitaltek.co.in/3.8/lib/python3.8/site-packages/django/urls/conf.py", line 38, in include
    urlconf_module = import_module(urlconf_module)
  File "/opt/alt/python38/lib64/python3.8/importlib/__init__.py", line 127, in import_module
    return _bootstrap._gcd_import(name[level:], package, level)
  File "<frozen importlib._bootstrap>", line 1014, in _gcd_import
  File "<frozen importlib._bootstrap>", line 991, in _find_and_load
  File "<frozen importlib._bootstrap>", line 975, in _find_and_load_unlocked
  File "<frozen importlib._bootstrap>", line 671, in _load_unlocked
  File "<frozen importlib._bootstrap_external>", line 843, in exec_module
  File "<frozen importlib._bootstrap>", line 219, in _call_with_frames_removed
  File "/home/xgrdscpi/api.lulucollection-52.digitaltek.co.in/dashboard/urls.py", line 4, in <module>
    from dashboard.views import (  
  File "/home/xgrdscpi/api.lulucollection-52.digitaltek.co.in/dashboard/views.py", line 7, in <module>
    from dashboard.serializers import (CategorySerializer, ContactUsSerializer,AboutUsSerializer,
ImportError: cannot import name 'AboutUsSerializer' from 'dashboard.serializers' (/home/xgrdscpi/api.lulucollection-52.digitaltek.co.in/dashboard/serializers.py)

During handling of the above exception, another exception occurred:

Traceback (most recent call last):
  File "/home/xgrdscpi/virtualenv/api.lulucollection-52.digitaltek.co.in/3.8/lib/python3.8/site-packages/django/core/handlers/exception.py", line 55, in inner
    response = get_response(request)
  File "/home/xgrdscpi/virtualenv/api.lulucollection-52.digitaltek.co.in/3.8/lib/python3.8/site-packages/django/utils/deprecation.py", line 134, in __call__
    response = response or self.get_response(request)
  File "/home/xgrdscpi/virtualenv/api.lulucollection-52.digitaltek.co.in/3.8/lib/python3.8/site-packages/django/core/handlers/exception.py", line 57, in inner
    response = response_for_exception(request, exc)
  File "/home/xgrdscpi/virtualenv/api.lulucollection-52.digitaltek.co.in/3.8/lib/python3.8/site-packages/django/core/handlers/exception.py", line 140, in response_for_exception
    response = handle_uncaught_exception(
  File "/home/xgrdscpi/virtualenv/api.lulucollection-52.digitaltek.co.in/3.8/lib/python3.8/site-packages/django/core/handlers/exception.py", line 184, in handle_uncaught_exception
    callback = resolver.resolve_error_handler(500)
  File "/home/xgrdscpi/virtualenv/api.lulucollection-52.digitaltek.co.in/3.8/lib/python3.8/site-packages/django/urls/resolvers.py", line 729, in resolve_error_handler
    callback = getattr(self.urlconf_module, "handler%s" % view_type, None)
  File "/home/xgrdscpi/virtualenv/api.lulucollection-52.digitaltek.co.in/3.8/lib/python3.8/site-packages/django/utils/functional.py", line 57, in __get__
    res = instance.__dict__[self.name] = self.func(instance)
  File "/home/xgrdscpi/virtualenv/api.lulucollection-52.digitaltek.co.in/3.8/lib/python3.8/site-packages/django/urls/resolvers.py", line 708, in urlconf_module
    return import_module(self.urlconf_name)
  File "/opt/alt/python38/lib64/python3.8/importlib/__init__.py", line 127, in import_module
    return _bootstrap._gcd_import(name[level:], package, level)
  File "<frozen importlib._bootstrap>", line 1014, in _gcd_import
  File "<frozen importlib._bootstrap>", line 991, in _find_and_load
  File "<frozen importlib._bootstrap>", line 975, in _find_and_load_unlocked
  File "<frozen importlib._bootstrap>", line 671, in _load_unlocked
  File "<frozen importlib._bootstrap_external>", line 843, in exec_module
  File "<frozen importlib._bootstrap>", line 219, in _call_with_frames_removed
  File "/home/xgrdscpi/api.lulucollection-52.digitaltek.co.in/backend/urls.py", line 33, in <module>
    path('api/', include('dashboard.urls')),
  File "/home/xgrdscpi/virtualenv/api.lulucollection-52.digitaltek.co.in/3.8/lib/python3.8/site-packages/django/urls/conf.py", line 38, in include
    urlconf_module = import_module(urlconf_module)
  File "/opt/alt/python38/lib64/python3.8/importlib/__init__.py", line 127, in import_module
    return _bootstrap._gcd_import(name[level:], package, level)
  File "<frozen importlib._bootstrap>", line 1014, in _gcd_import
  File "<frozen importlib._bootstrap>", line 991, in _find_and_load
  File "<frozen importlib._bootstrap>", line 975, in _find_and_load_unlocked
  File "<frozen importlib._bootstrap>", line 671, in _load_unlocked
  File "<frozen importlib._bootstrap_external>", line 843, in exec_module
  File "<frozen importlib._bootstrap>", line 219, in _call_with_frames_removed
  File "/home/xgrdscpi/api.lulucollection-52.digitaltek.co.in/dashboard/urls.py", line 4, in <module>
    from dashboard.views import (  
  File "/home/xgrdscpi/api.lulucollection-52.digitaltek.co.in/dashboard/views.py", line 7, in <module>
    from dashboard.serializers import (CategorySerializer, ContactUsSerializer,AboutUsSerializer,
ImportError: cannot import name 'AboutUsSerializer' from 'dashboard.serializers' (/home/xgrdscpi/api.lulucollection-52.digitaltek.co.in/dashboard/serializers.py)

During handling of the above exception, another exception occurred:

Traceback (most recent call last):
  File "/home/xgrdscpi/virtualenv/api.lulucollection-52.digitaltek.co.in/3.8/lib/python3.8/site-packages/django/core/handlers/exception.py", line 55, in inner
    response = get_response(request)
  File "/home/xgrdscpi/virtualenv/api.lulucollection-52.digitaltek.co.in/3.8/lib/python3.8/site-packages/corsheaders/middleware.py", line 56, in __call__
    result = self.get_response(request)
  File "/home/xgrdscpi/virtualenv/api.lulucollection-52.digitaltek.co.in/3.8/lib/python3.8/site-packages/django/core/handlers/exception.py", line 57, in inner
    response = response_for_exception(request, exc)
  File "/home/xgrdscpi/virtualenv/api.lulucollection-52.digitaltek.co.in/3.8/lib/python3.8/site-packages/django/core/handlers/exception.py", line 140, in response_for_exception
    response = handle_uncaught_exception(
  File "/home/xgrdscpi/virtualenv/api.lulucollection-52.digitaltek.co.in/3.8/lib/python3.8/site-packages/django/core/handlers/exception.py", line 184, in handle_uncaught_exception
    callback = resolver.resolve_error_handler(500)
  File "/home/xgrdscpi/virtualenv/api.lulucollection-52.digitaltek.co.in/3.8/lib/python3.8/site-packages/django/urls/resolvers.py", line 729, in resolve_error_handler
    callback = getattr(self.urlconf_module, "handler%s" % view_type, None)
  File "/opt/alt/python38/lib64/python3.8/importlib/__init__.py", line 127, in import_module
    return _bootstrap._gcd_import(name[level:], package, level)
  File "<frozen importlib._bootstrap>", line 1014, in _gcd_import
  File "<frozen importlib._bootstrap>", line 991, in _find_and_load
  File "<frozen importlib._bootstrap>", line 975, in _find_and_load_unlocked
  File "<frozen importlib._bootstrap>", line 671, in _load_unlocked
  File "<frozen importlib._bootstrap_external>", line 843, in exec_module
  File "<frozen importlib._bootstrap>", line 219, in _call_with_frames_removed
  File "/home/xgrdscpi/api.lulucollection-52.digitaltek.co.in/backend/urls.py", line 33, in <module>
    path('api/', include('dashboard.urls')),
  File "/home/xgrdscpi/virtualenv/api.lulucollection-52.digitaltek.co.in/3.8/lib/python3.8/site-packages/django/urls/conf.py", line 38, in include
    urlconf_module = import_module(urlconf_module)
  File "/opt/alt/python38/lib64/python3.8/importlib/__init__.py", line 127, in import_module
    return _bootstrap._gcd_import(name[level:], package, level)
  File "<frozen importlib._bootstrap>", line 1014, in _gcd_import
  File "<frozen importlib._bootstrap>", line 991, in _find_and_load
  File "<frozen importlib._bootstrap>", line 975, in _find_and_load_unlocked
  File "<frozen importlib._bootstrap>", line 671, in _load_unlocked
  File "<frozen importlib._bootstrap_external>", line 843, in exec_module
  File "<frozen importlib._bootstrap>", line 219, in _call_with_frames_removed
  File "/home/xgrdscpi/api.lulucollection-52.digitaltek.co.in/dashboard/urls.py", line 4, in <module>
    from dashboard.views import (  
  File "/home/xgrdscpi/api.lulucollection-52.digitaltek.co.in/dashboard/views.py", line 7, in <module>
    from dashboard.serializers import (CategorySerializer, ContactUsSerializer,AboutUsSerializer,
ImportError: cannot import name 'AboutUsSerializer' from 'dashboard.serializers' (/home/xgrdscpi/api.lulucollection-52.digitaltek.co.in/dashboard/serializers.py)

During handling of the above exception, another exception occurred:

Traceback (most recent call last):
  File "/home/xgrdscpi/virtualenv/api.lulucollection-52.digitaltek.co.in/3.8/lib/python3.8/site-packages/django/core/handlers/wsgi.py", line 124, in __call__
    response = self.get_response(request)
  File "/home/xgrdscpi/virtualenv/api.lulucollection-52.digitaltek.co.in/3.8/lib/python3.8/site-packages/django/core/handlers/base.py", line 140, in get_response
    response = self._middleware_chain(request)
  File "/home/xgrdscpi/virtualenv/api.lulucollection-52.digitaltek.co.in/3.8/lib/python3.8/site-packages/django/core/handlers/exception.py", line 57, in inner
    response = response_for_exception(request, exc)
  File "/home/xgrdscpi/virtualenv/api.lulucollection-52.digitaltek.co.in/3.8/lib/python3.8/site-packages/django/core/handlers/exception.py", line 140, in response_for_exception
    response = handle_uncaught_exception(
  File "/home/xgrdscpi/virtualenv/api.lulucollection-52.digitaltek.co.in/3.8/lib/python3.8/site-packages/django/core/handlers/exception.py", line 184, in handle_uncaught_exception
    callback = resolver.resolve_error_handler(500)
  File "/home/xgrdscpi/virtualenv/api.lulucollection-52.digitaltek.co.in/3.8/lib/python3.8/site-packages/django/urls/resolvers.py", line 729, in resolve_error_handler
    callback = getattr(self.urlconf_module, "handler%s" % view_type, None)
  File "/home/xgrdscpi/virtualenv/api.lulucollection-52.digitaltek.co.in/3.8/lib/python3.8/site-packages/django/utils/functional.py", line 57, in __get__
    res = instance.__dict__[self.name] = self.func(instance)
  File "/home/xgrdscpi/virtualenv/api.lulucollection-52.digitaltek.co.in/3.8/lib/python3.8/site-packages/django/urls/resolvers.py", line 708, in urlconf_module
    return import_module(self.urlconf_name)
  File "/opt/alt/python38/lib64/python3.8/importlib/__init__.py", line 127, in import_module
    return _bootstrap._gcd_import(name[level:], package, level)
  File "<frozen importlib._bootstrap>", line 1014, in _gcd_import
  File "<frozen importlib._bootstrap>", line 991, in _find_and_load
  File "<frozen importlib._bootstrap>", line 975, in _find_and_load_unlocked
  File "<frozen importlib._bootstrap>", line 671, in _load_unlocked
  File "<frozen importlib._bootstrap_external>", line 843, in exec_module
  File "<frozen importlib._bootstrap>", line 219, in _call_with_frames_removed
  File "/home/xgrdscpi/api.lulucollection-52.digitaltek.co.in/backend/urls.py", line 33, in <module>
    path('api/', include('dashboard.urls')),
  File "/home/xgrdscpi/virtualenv/api.lulucollection-52.digitaltek.co.in/3.8/lib/python3.8/site-packages/django/urls/conf.py", line 38, in include
    urlconf_module = import_module(urlconf_module)
  File "/opt/alt/python38/lib64/python3.8/importlib/__init__.py", line 127, in import_module
    return _bootstrap._gcd_import(name[level:], package, level)
  File "<frozen importlib._bootstrap>", line 1014, in _gcd_import
  File "<frozen importlib._bootstrap>", line 991, in _find_and_load
  File "<frozen importlib._bootstrap>", line 975, in _find_and_load_unlocked
  File "<frozen importlib._bootstrap>", line 671, in _load_unlocked
  File "<frozen importlib._bootstrap_external>", line 843, in exec_module
  File "<frozen importlib._bootstrap>", line 219, in _call_with_frames_removed
  File "/home/xgrdscpi/api.lulucollection-52.digitaltek.co.in/dashboard/urls.py", line 4, in <module>
    from dashboard.views import (  
  File "/home/xgrdscpi/api.lulucollection-52.digitaltek.co.in/dashboard/views.py", line 7, in <module>
    from dashboard.serializers import (CategorySerializer, ContactUsSerializer,AboutUsSerializer,
ImportError: cannot import name 'AboutUsSerializer' from 'dashboard.serializers' (/home/xgrdscpi/api.lulucollection-52.digitaltek.co.in/dashboard/serializers.py)
  File "/home/xgrdscpi/virtualenv/api.lulucollection-52.digitaltek.co.in/3.8/lib/python3.8/site-packages/django/utils/functional.py", line 57, in __get__
    res = instance.__dict__[self.name] = self.func(instance)
  File "/home/xgrdscpi/virtualenv/api.lulucollection-52.digitaltek.co.in/3.8/lib/python3.8/site-packages/django/urls/resolvers.py", line 708, in urlconf_module
    return import_module(self.urlconf_name)
  File "/opt/alt/python38/lib64/python3.8/importlib/__init__.py", line 127, in import_module
    return _bootstrap._gcd_import(name[level:], package, level)
  File "<frozen importlib._bootstrap>", line 1014, in _gcd_import
  File "<frozen importlib._bootstrap>", line 991, in _find_and_load
  File "<frozen importlib._bootstrap>", line 975, in _find_and_load_unlocked
  File "<frozen importlib._bootstrap>", line 671, in _load_unlocked
  File "<frozen importlib._bootstrap_external>", line 843, in exec_module
  File "<frozen importlib._bootstrap>", line 219, in _call_with_frames_removed
  File "/home/xgrdscpi/api.lulucollection-52.digitaltek.co.in/backend/urls.py", line 33, in <module>
    path('api/', include('dashboard.urls')),
  File "/home/xgrdscpi/virtualenv/api.lulucollection-52.digitaltek.co.in/3.8/lib/python3.8/site-packages/django/urls/conf.py", line 38, in include
    urlconf_module = import_module(urlconf_module)
  File "/opt/alt/python38/lib64/python3.8/importlib/__init__.py", line 127, in import_module
    return _bootstrap._gcd_import(name[level:], package, level)
  File "<frozen importlib._bootstrap>", line 1014, in _gcd_import
  File "<frozen importlib._bootstrap>", line 991, in _find_and_load
  File "<frozen importlib._bootstrap>", line 975, in _find_and_load_unlocked
  File "<frozen importlib._bootstrap>", line 671, in _load_unlocked
  File "<frozen importlib._bootstrap_external>", line 843, in exec_module
  File "<frozen importlib._bootstrap>", line 219, in _call_with_frames_removed
  File "/home/xgrdscpi/api.lulucollection-52.digitaltek.co.in/dashboard/urls.py", line 4, in <module>
    from dashboard.views import (  
  File "/home/xgrdscpi/api.lulucollection-52.digitaltek.co.in/dashboard/views.py", line 7, in <module>
    from dashboard.serializers import (CategorySerializer, ContactUsSerializer,AboutUsSerializer,
ImportError: cannot import name 'AboutUsSerializer' from 'dashboard.serializers' (/home/xgrdscpi/api.lulucollection-52.digitaltek.co.in/dashboard/serializers.py)

During handling of the above exception, another exception occurred:

Traceback (most recent call last):
  File "/home/xgrdscpi/virtualenv/api.lulucollection-52.digitaltek.co.in/3.8/lib/python3.8/site-packages/django/core/handlers/exception.py", line 55, in inner
    response = get_response(request)
  File "/home/xgrdscpi/virtualenv/api.lulucollection-52.digitaltek.co.in/3.8/lib/python3.8/site-packages/django/utils/deprecation.py", line 134, in __call__
    response = response or self.get_response(request)
  File "/home/xgrdscpi/virtualenv/api.lulucollection-52.digitaltek.co.in/3.8/lib/python3.8/site-packages/django/core/handlers/exception.py", line 57, in inner
    response = response_for_exception(request, exc)
  File "/home/xgrdscpi/virtualenv/api.lulucollection-52.digitaltek.co.in/3.8/lib/python3.8/site-packages/django/core/handlers/exception.py", line 140, in response_for_exception
    response = handle_uncaught_exception(
  File "/home/xgrdscpi/virtualenv/api.lulucollection-52.digitaltek.co.in/3.8/lib/python3.8/site-packages/django/core/handlers/exception.py", line 184, in handle_uncaught_exception
    callback = resolver.resolve_error_handler(500)
  File "/home/xgrdscpi/virtualenv/api.lulucollection-52.digitaltek.co.in/3.8/lib/python3.8/site-packages/django/urls/resolvers.py", line 729, in resolve_error_handler
    callback = getattr(self.urlconf_module, "handler%s" % view_type, None)
  File "/home/xgrdscpi/virtualenv/api.lulucollection-52.digitaltek.co.in/3.8/lib/python3.8/site-packages/django/utils/functional.py", line 57, in __get__
    res = instance.__dict__[self.name] = self.func(instance)
  File "/home/xgrdscpi/virtualenv/api.lulucollection-52.digitaltek.co.in/3.8/lib/python3.8/site-packages/django/urls/resolvers.py", line 708, in urlconf_module
    return import_module(self.urlconf_name)
  File "/opt/alt/python38/lib64/python3.8/importlib/__init__.py", line 127, in import_module
    return _bootstrap._gcd_import(name[level:], package, level)
  File "<frozen importlib._bootstrap>", line 1014, in _gcd_import
  File "<frozen importlib._bootstrap>", line 991, in _find_and_load
  File "<frozen importlib._bootstrap>", line 975, in _find_and_load_unlocked
  File "<frozen importlib._bootstrap>", line 671, in _load_unlocked
  File "<frozen importlib._bootstrap_external>", line 843, in exec_module
  File "<frozen importlib._bootstrap>", line 219, in _call_with_frames_removed
  File "/home/xgrdscpi/api.lulucollection-52.digitaltek.co.in/backend/urls.py", line 33, in <module>
    path('api/', include('dashboard.urls')),
  File "/home/xgrdscpi/virtualenv/api.lulucollection-52.digitaltek.co.in/3.8/lib/python3.8/site-packages/django/urls/conf.py", line 38, in include
    urlconf_module = import_module(urlconf_module)
  File "/opt/alt/python38/lib64/python3.8/importlib/__init__.py", line 127, in import_module
    return _bootstrap._gcd_import(name[level:], package, level)
  File "<frozen importlib._bootstrap>", line 1014, in _gcd_import
  File "<frozen importlib._bootstrap>", line 991, in _find_and_load
  File "<frozen importlib._bootstrap>", line 975, in _find_and_load_unlocked
  File "<frozen importlib._bootstrap>", line 671, in _load_unlocked
  File "<frozen importlib._bootstrap_external>", line 843, in exec_module
  File "<frozen importlib._bootstrap>", line 219, in _call_with_frames_removed
  File "/home/xgrdscpi/api.lulucollection-52.digitaltek.co.in/dashboard/urls.py", line 4, in <module>
    from dashboard.views import (  
  File "/home/xgrdscpi/api.lulucollection-52.digitaltek.co.in/dashboard/views.py", line 7, in <module>
    from dashboard.serializers import (CategorySerializer, ContactUsSerializer,AboutUsSerializer,
ImportError: cannot import name 'AboutUsSerializer' from 'dashboard.serializers' (/home/xgrdscpi/api.lulucollection-52.digitaltek.co.in/dashboard/serializers.py)

During handling of the above exception, another exception occurred:

Traceback (most recent call last):
  File "/home/xgrdscpi/virtualenv/api.lulucollection-52.digitaltek.co.in/3.8/lib/python3.8/site-packages/django/core/handlers/exception.py", line 55, in inner
    response = get_response(request)
  File "/home/xgrdscpi/virtualenv/api.lulucollection-52.digitaltek.co.in/3.8/lib/python3.8/site-packages/django/utils/deprecation.py", line 134, in __call__
    response = response or self.get_response(request)
  File "/home/xgrdscpi/virtualenv/api.lulucollection-52.digitaltek.co.in/3.8/lib/python3.8/site-packages/django/core/handlers/exception.py", line 57, in inner
    response = response_for_exception(request, exc)
  File "/home/xgrdscpi/virtualenv/api.lulucollection-52.digitaltek.co.in/3.8/lib/python3.8/site-packages/django/core/handlers/exception.py", line 140, in response_for_exception
    response = handle_uncaught_exception(
  File "/home/xgrdscpi/virtualenv/api.lulucollection-52.digitaltek.co.in/3.8/lib/python3.8/site-packages/django/core/handlers/exception.py", line 184, in handle_uncaught_exception
    callback = resolver.resolve_error_handler(500)
  File "/home/xgrdscpi/virtualenv/api.lulucollection-52.digitaltek.co.in/3.8/lib/python3.8/site-packages/django/urls/resolvers.py", line 729, in resolve_error_handler
    callback = getattr(self.urlconf_module, "handler%s" % view_type, None)
  File "/home/xgrdscpi/virtualenv/api.lulucollection-52.digitaltek.co.in/3.8/lib/python3.8/site-packages/django/utils/functional.py", line 57, in __get__
    res = instance.__dict__[self.name] = self.func(instance)
  File "/home/xgrdscpi/virtualenv/api.lulucollection-52.digitaltek.co.in/3.8/lib/python3.8/site-packages/django/urls/resolvers.py", line 708, in urlconf_module
    return import_module(self.urlconf_name)
  File "/opt/alt/python38/lib64/python3.8/importlib/__init__.py", line 127, in import_module
    return _bootstrap._gcd_import(name[level:], package, level)
  File "<frozen importlib._bootstrap>", line 1014, in _gcd_import
  File "<frozen importlib._bootstrap>", line 991, in _find_and_load
  File "<frozen importlib._bootstrap>", line 975, in _find_and_load_unlocked
  File "<frozen importlib._bootstrap>", line 671, in _load_unlocked
  File "<frozen importlib._bootstrap_external>", line 843, in exec_module
  File "<frozen importlib._bootstrap>", line 219, in _call_with_frames_removed
  File "/home/xgrdscpi/api.lulucollection-52.digitaltek.co.in/backend/urls.py", line 33, in <module>
    path('api/', include('dashboard.urls')),
  File "/home/xgrdscpi/virtualenv/api.lulucollection-52.digitaltek.co.in/3.8/lib/python3.8/site-packages/django/urls/conf.py", line 38, in include
    urlconf_module = import_module(urlconf_module)
  File "/opt/alt/python38/lib64/python3.8/importlib/__init__.py", line 127, in import_module
    return _bootstrap._gcd_import(name[level:], package, level)
  File "<frozen importlib._bootstrap>", line 1014, in _gcd_import
  File "<frozen importlib._bootstrap>", line 991, in _find_and_load
  File "<frozen importlib._bootstrap>", line 975, in _find_and_load_unlocked
  File "<frozen importlib._bootstrap>", line 671, in _load_unlocked
  File "<frozen importlib._bootstrap_external>", line 843, in exec_module
  File "<frozen importlib._bootstrap>", line 219, in _call_with_frames_removed
  File "/home/xgrdscpi/api.lulucollection-52.digitaltek.co.in/dashboard/urls.py", line 4, in <module>
    from dashboard.views import (  
  File "/home/xgrdscpi/api.lulucollection-52.digitaltek.co.in/dashboard/views.py", line 7, in <module>
    from dashboard.serializers import (CategorySerializer, ContactUsSerializer,AboutUsSerializer,
ImportError: cannot import name 'AboutUsSerializer' from 'dashboard.serializers' (/home/xgrdscpi/api.lulucollection-52.digitaltek.co.in/dashboard/serializers.py)

During handling of the above exception, another exception occurred:

Traceback (most recent call last):
  File "/home/xgrdscpi/virtualenv/api.lulucollection-52.digitaltek.co.in/3.8/lib/python3.8/site-packages/django/core/handlers/wsgi.py", line 124, in __call__
    response = self.get_response(request)
  File "/home/xgrdscpi/virtualenv/api.lulucollection-52.digitaltek.co.in/3.8/lib/python3.8/site-packages/django/core/handlers/base.py", line 140, in get_response
    response = self._middleware_chain(request)
  File "/home/xgrdscpi/virtualenv/api.lulucollection-52.digitaltek.co.in/3.8/lib/python3.8/site-packages/django/core/handlers/exception.py", line 57, in inner
    response = response_for_exception(request, exc)
  File "/home/xgrdscpi/virtualenv/api.lulucollection-52.digitaltek.co.in/3.8/lib/python3.8/site-packages/django/core/handlers/exception.py", line 140, in response_for_exception
    response = handle_uncaught_exception(
  File "/home/xgrdscpi/virtualenv/api.lulucollection-52.digitaltek.co.in/3.8/lib/python3.8/site-packages/django/core/handlers/exception.py", line 184, in handle_uncaught_exception
    callback = resolver.resolve_error_handler(500)
  File "/home/xgrdscpi/virtualenv/api.lulucollection-52.digitaltek.co.in/3.8/lib/python3.8/site-packages/django/urls/resolvers.py", line 729, in resolve_error_handler
    callback = getattr(self.urlconf_module, "handler%s" % view_type, None)
  File "/home/xgrdscpi/virtualenv/api.lulucollection-52.digitaltek.co.in/3.8/lib/python3.8/site-packages/django/utils/functional.py", line 57, in __get__
    res = instance.__dict__[self.name] = self.func(instance)
  File "/home/xgrdscpi/virtualenv/api.lulucollection-52.digitaltek.co.in/3.8/lib/python3.8/site-packages/django/urls/resolvers.py", line 708, in urlconf_module
    return import_module(self.urlconf_name)
  File "/opt/alt/python38/lib64/python3.8/importlib/__init__.py", line 127, in import_module
    return _bootstrap._gcd_import(name[level:], package, level)
  File "<frozen importlib._bootstrap>", line 1014, in _gcd_import
  File "<frozen importlib._bootstrap>", line 991, in _find_and_load
  File "<frozen importlib._bootstrap>", line 975, in _find_and_load_unlocked
  File "<frozen importlib._bootstrap>", line 671, in _load_unlocked
  File "<frozen importlib._bootstrap_external>", line 843, in exec_module
  File "<frozen importlib._bootstrap>", line 219, in _call_with_frames_removed
  File "/home/xgrdscpi/api.lulucollection-52.digitaltek.co.in/backend/urls.py", line 33, in <module>
    path('api/', include('dashboard.urls')),
  File "/home/xgrdscpi/virtualenv/api.lulucollection-52.digitaltek.co.in/3.8/lib/python3.8/site-packages/django/urls/conf.py", line 38, in include
    urlconf_module = import_module(urlconf_module)
  File "/opt/alt/python38/lib64/python3.8/importlib/__init__.py", line 127, in import_module
    return _bootstrap._gcd_import(name[level:], package, level)
  File "<frozen importlib._bootstrap>", line 1014, in _gcd_import
  File "<frozen importlib._bootstrap>", line 991, in _find_and_load
  File "<frozen importlib._bootstrap>", line 975, in _find_and_load_unlocked
  File "<frozen importlib._bootstrap>", line 671, in _load_unlocked
  File "<frozen importlib._bootstrap_external>", line 843, in exec_module
  File "<frozen importlib._bootstrap>", line 219, in _call_with_frames_removed
  File "/home/xgrdscpi/api.lulucollection-52.digitaltek.co.in/dashboard/urls.py", line 4, in <module>
    from dashboard.views import (  
  File "/home/xgrdscpi/api.lulucollection-52.digitaltek.co.in/dashboard/views.py", line 7, in <module>
    from dashboard.serializers import (CategorySerializer, ContactUsSerializer,AboutUsSerializer,
ImportError: cannot import name 'AboutUsSerializer' from 'dashboard.serializers' (/home/xgrdscpi/api.lulucollection-52.digitaltek.co.in/dashboard/serializers.py)
[ERROR] [UID:4986][3129230] wsgiAppHandler pApp->start_response() return NULL.
Traceback (most recent call last):
  File "/home/xgrdscpi/virtualenv/api.lulucollection-52.digitaltek.co.in/3.8/lib/python3.8/site-packages/django/core/handlers/exception.py", line 55, in inner
    response = get_response(request)
  File "/home/xgrdscpi/virtualenv/api.lulucollection-52.digitaltek.co.in/3.8/lib/python3.8/site-packages/django/core/handlers/base.py", line 181, in _get_response
    callback, callback_args, callback_kwargs = self.resolve_request(request)
  File "/home/xgrdscpi/virtualenv/api.lulucollection-52.digitaltek.co.in/3.8/lib/python3.8/site-packages/django/core/handlers/base.py", line 313, in resolve_request
    resolver_match = resolver.resolve(request.path_info)
  File "/home/xgrdscpi/virtualenv/api.lulucollection-52.digitaltek.co.in/3.8/lib/python3.8/site-packages/django/urls/resolvers.py", line 663, in resolve
    for pattern in self.url_patterns:
  File "/home/xgrdscpi/virtualenv/api.lulucollection-52.digitaltek.co.in/3.8/lib/python3.8/site-packages/django/utils/functional.py", line 57, in __get__
    res = instance.__dict__[self.name] = self.func(instance)
  File "/home/xgrdscpi/virtualenv/api.lulucollection-52.digitaltek.co.in/3.8/lib/python3.8/site-packages/django/urls/resolvers.py", line 715, in url_patterns
    patterns = getattr(self.urlconf_module, "urlpatterns", self.urlconf_module)
  File "/home/xgrdscpi/virtualenv/api.lulucollection-52.digitaltek.co.in/3.8/lib/python3.8/site-packages/django/utils/functional.py", line 57, in __get__
    res = instance.__dict__[self.name] = self.func(instance)
  File "/home/xgrdscpi/virtualenv/api.lulucollection-52.digitaltek.co.in/3.8/lib/python3.8/site-packages/django/urls/resolvers.py", line 708, in urlconf_module
    return import_module(self.urlconf_name)
  File "/opt/alt/python38/lib64/python3.8/importlib/__init__.py", line 127, in import_module
    return _bootstrap._gcd_import(name[level:], package, level)
  File "<frozen importlib._bootstrap>", line 1014, in _gcd_import
  File "<frozen importlib._bootstrap>", line 991, in _find_and_load
  File "<frozen importlib._bootstrap>", line 975, in _find_and_load_unlocked
  File "<frozen importlib._bootstrap>", line 671, in _load_unlocked
  File "<frozen importlib._bootstrap_external>", line 843, in exec_module
  File "<frozen importlib._bootstrap>", line 219, in _call_with_frames_removed
  File "/home/xgrdscpi/api.lulucollection-52.digitaltek.co.in/backend/urls.py", line 33, in <module>
    path('api/', include('dashboard.urls')),
  File "/home/xgrdscpi/virtualenv/api.lulucollection-52.digitaltek.co.in/3.8/lib/python3.8/site-packages/django/urls/conf.py", line 38, in include
    urlconf_module = import_module(urlconf_module)
  File "/opt/alt/python38/lib64/python3.8/importlib/__init__.py", line 127, in import_module
    return _bootstrap._gcd_import(name[level:], package, level)
  File "<frozen importlib._bootstrap>", line 1014, in _gcd_import
  File "<frozen importlib._bootstrap>", line 991, in _find_and_load
  File "<frozen importlib._bootstrap>", line 975, in _find_and_load_unlocked
  File "<frozen importlib._bootstrap>", line 671, in _load_unlocked
  File "<frozen importlib._bootstrap_external>", line 843, in exec_module
  File "<frozen importlib._bootstrap>", line 219, in _call_with_frames_removed
  File "/home/xgrdscpi/api.lulucollection-52.digitaltek.co.in/dashboard/urls.py", line 109, in <module>
    path('about-us/', AboutUsView.as_view(), name='about-us'),
NameError: name 'AboutUsView' is not defined

During handling of the above exception, another exception occurred:

Traceback (most recent call last):
  File "/home/xgrdscpi/virtualenv/api.lulucollection-52.digitaltek.co.in/3.8/lib/python3.8/site-packages/django/core/handlers/exception.py", line 55, in inner
    response = get_response(request)
  File "/home/xgrdscpi/virtualenv/api.lulucollection-52.digitaltek.co.in/3.8/lib/python3.8/site-packages/django/utils/deprecation.py", line 134, in __call__
    response = response or self.get_response(request)
  File "/home/xgrdscpi/virtualenv/api.lulucollection-52.digitaltek.co.in/3.8/lib/python3.8/site-packages/django/core/handlers/exception.py", line 57, in inner
    response = response_for_exception(request, exc)
  File "/home/xgrdscpi/virtualenv/api.lulucollection-52.digitaltek.co.in/3.8/lib/python3.8/site-packages/django/core/handlers/exception.py", line 140, in response_for_exception
    response = handle_uncaught_exception(
  File "/home/xgrdscpi/virtualenv/api.lulucollection-52.digitaltek.co.in/3.8/lib/python3.8/site-packages/django/core/handlers/exception.py", line 184, in handle_uncaught_exception
    callback = resolver.resolve_error_handler(500)
  File "/home/xgrdscpi/virtualenv/api.lulucollection-52.digitaltek.co.in/3.8/lib/python3.8/site-packages/django/urls/resolvers.py", line 729, in resolve_error_handler
    callback = getattr(self.urlconf_module, "handler%s" % view_type, None)
  File "/home/xgrdscpi/virtualenv/api.lulucollection-52.digitaltek.co.in/3.8/lib/python3.8/site-packages/django/utils/functional.py", line 57, in __get__
    res = instance.__dict__[self.name] = self.func(instance)
  File "/home/xgrdscpi/virtualenv/api.lulucollection-52.digitaltek.co.in/3.8/lib/python3.8/site-packages/django/urls/resolvers.py", line 708, in urlconf_module
    return import_module(self.urlconf_name)
  File "/opt/alt/python38/lib64/python3.8/importlib/__init__.py", line 127, in import_module
    return _bootstrap._gcd_import(name[level:], package, level)
  File "<frozen importlib._bootstrap>", line 1014, in _gcd_import
  File "<frozen importlib._bootstrap>", line 991, in _find_and_load
  File "<frozen importlib._bootstrap>", line 975, in _find_and_load_unlocked
  File "<frozen importlib._bootstrap>", line 671, in _load_unlocked
  File "<frozen importlib._bootstrap_external>", line 843, in exec_module
  File "<frozen importlib._bootstrap>", line 219, in _call_with_frames_removed
  File "/home/xgrdscpi/api.lulucollection-52.digitaltek.co.in/backend/urls.py", line 33, in <module>
    path('api/', include('dashboard.urls')),
  File "/home/xgrdscpi/virtualenv/api.lulucollection-52.digitaltek.co.in/3.8/lib/python3.8/site-packages/django/urls/conf.py", line 38, in include
    urlconf_module = import_module(urlconf_module)
  File "/opt/alt/python38/lib64/python3.8/importlib/__init__.py", line 127, in import_module
    return _bootstrap._gcd_import(name[level:], package, level)
  File "<frozen importlib._bootstrap>", line 1014, in _gcd_import
  File "<frozen importlib._bootstrap>", line 991, in _find_and_load
  File "<frozen importlib._bootstrap>", line 975, in _find_and_load_unlocked
  File "<frozen importlib._bootstrap>", line 671, in _load_unlocked
  File "<frozen importlib._bootstrap_external>", line 843, in exec_module
  File "<frozen importlib._bootstrap>", line 219, in _call_with_frames_removed
  File "/home/xgrdscpi/api.lulucollection-52.digitaltek.co.in/dashboard/urls.py", line 109, in <module>
    path('about-us/', AboutUsView.as_view(), name='about-us'),
NameError: name 'AboutUsView' is not defined

During handling of the above exception, another exception occurred:

Traceback (most recent call last):
  File "/home/xgrdscpi/virtualenv/api.lulucollection-52.digitaltek.co.in/3.8/lib/python3.8/site-packages/django/core/handlers/exception.py", line 55, in inner
    response = get_response(request)
  File "/home/xgrdscpi/virtualenv/api.lulucollection-52.digitaltek.co.in/3.8/lib/python3.8/site-packages/django/utils/deprecation.py", line 134, in __call__
    response = response or self.get_response(request)
  File "/home/xgrdscpi/virtualenv/api.lulucollection-52.digitaltek.co.in/3.8/lib/python3.8/site-packages/django/core/handlers/exception.py", line 57, in inner
    response = response_for_exception(request, exc)
  File "/home/xgrdscpi/virtualenv/api.lulucollection-52.digitaltek.co.in/3.8/lib/python3.8/site-packages/django/core/handlers/exception.py", line 140, in response_for_exception
    response = handle_uncaught_exception(
  File "/home/xgrdscpi/virtualenv/api.lulucollection-52.digitaltek.co.in/3.8/lib/python3.8/site-packages/django/core/handlers/exception.py", line 184, in handle_uncaught_exception
    callback = resolver.resolve_error_handler(500)
  File "/home/xgrdscpi/virtualenv/api.lulucollection-52.digitaltek.co.in/3.8/lib/python3.8/site-packages/django/urls/resolvers.py", line 729, in resolve_error_handler
    callback = getattr(self.urlconf_module, "handler%s" % view_type, None)
  File "/home/xgrdscpi/virtualenv/api.lulucollection-52.digitaltek.co.in/3.8/lib/python3.8/site-packages/django/utils/functional.py", line 57, in __get__
    res = instance.__dict__[self.name] = self.func(instance)
  File "/home/xgrdscpi/virtualenv/api.lulucollection-52.digitaltek.co.in/3.8/lib/python3.8/site-packages/django/urls/resolvers.py", line 708, in urlconf_module
    return import_module(self.urlconf_name)
  File "/opt/alt/python38/lib64/python3.8/importlib/__init__.py", line 127, in import_module
    return _bootstrap._gcd_import(name[level:], package, level)
  File "<frozen importlib._bootstrap>", line 1014, in _gcd_import
  File "<frozen importlib._bootstrap>", line 991, in _find_and_load
  File "<frozen importlib._bootstrap>", line 975, in _find_and_load_unlocked
  File "<frozen importlib._bootstrap>", line 671, in _load_unlocked
  File "<frozen importlib._bootstrap_external>", line 843, in exec_module
  File "<frozen importlib._bootstrap>", line 219, in _call_with_frames_removed
  File "/home/xgrdscpi/api.lulucollection-52.digitaltek.co.in/backend/urls.py", line 33, in <module>
    path('api/', include('dashboard.urls')),
  File "/home/xgrdscpi/virtualenv/api.lulucollection-52.digitaltek.co.in/3.8/lib/python3.8/site-packages/django/urls/conf.py", line 38, in include
    urlconf_module = import_module(urlconf_module)
  File "/opt/alt/python38/lib64/python3.8/importlib/__init__.py", line 127, in import_module
    return _bootstrap._gcd_import(name[level:], package, level)
  File "<frozen importlib._bootstrap>", line 1014, in _gcd_import
  File "<frozen importlib._bootstrap>", line 991, in _find_and_load
  File "<frozen importlib._bootstrap>", line 975, in _find_and_load_unlocked
  File "<frozen importlib._bootstrap>", line 671, in _load_unlocked
  File "<frozen importlib._bootstrap_external>", line 843, in exec_module
  File "<frozen importlib._bootstrap>", line 219, in _call_with_frames_removed
  File "/home/xgrdscpi/api.lulucollection-52.digitaltek.co.in/dashboard/urls.py", line 109, in <module>
    path('about-us/', AboutUsView.as_view(), name='about-us'),
NameError: name 'AboutUsView' is not defined

During handling of the above exception, another exception occurred:

Traceback (most recent call last):
  File "/home/xgrdscpi/virtualenv/api.lulucollection-52.digitaltek.co.in/3.8/lib/python3.8/site-packages/django/core/handlers/exception.py", line 55, in inner
    response = get_response(request)
  File "/home/xgrdscpi/virtualenv/api.lulucollection-52.digitaltek.co.in/3.8/lib/python3.8/site-packages/django/utils/deprecation.py", line 134, in __call__
    response = response or self.get_response(request)
  File "/home/xgrdscpi/virtualenv/api.lulucollection-52.digitaltek.co.in/3.8/lib/python3.8/site-packages/django/core/handlers/exception.py", line 57, in inner
    response = response_for_exception(request, exc)
  File "/home/xgrdscpi/virtualenv/api.lulucollection-52.digitaltek.co.in/3.8/lib/python3.8/site-packages/django/core/handlers/exception.py", line 140, in response_for_exception
    response = handle_uncaught_exception(
  File "/home/xgrdscpi/virtualenv/api.lulucollection-52.digitaltek.co.in/3.8/lib/python3.8/site-packages/django/core/handlers/exception.py", line 184, in handle_uncaught_exception
    callback = resolver.resolve_error_handler(500)
  File "/home/xgrdscpi/virtualenv/api.lulucollection-52.digitaltek.co.in/3.8/lib/python3.8/site-packages/django/urls/resolvers.py", line 729, in resolve_error_handler
    callback = getattr(self.urlconf_module, "handler%s" % view_type, None)
  File "/home/xgrdscpi/virtualenv/api.lulucollection-52.digitaltek.co.in/3.8/lib/python3.8/site-packages/django/utils/functional.py", line 57, in __get__
    res = instance.__dict__[self.name] = self.func(instance)
  File "/home/xgrdscpi/virtualenv/api.lulucollection-52.digitaltek.co.in/3.8/lib/python3.8/site-packages/django/urls/resolvers.py", line 708, in urlconf_module
    return import_module(self.urlconf_name)
  File "/opt/alt/python38/lib64/python3.8/importlib/__init__.py", line 127, in import_module
    return _bootstrap._gcd_import(name[level:], package, level)
  File "<frozen importlib._bootstrap>", line 1014, in _gcd_import
  File "<frozen importlib._bootstrap>", line 991, in _find_and_load
  File "<frozen importlib._bootstrap>", line 975, in _find_and_load_unlocked
  File "<frozen importlib._bootstrap>", line 671, in _load_unlocked
  File "<frozen importlib._bootstrap_external>", line 843, in exec_module
  File "<frozen importlib._bootstrap>", line 219, in _call_with_frames_removed
  File "/home/xgrdscpi/api.lulucollection-52.digitaltek.co.in/backend/urls.py", line 33, in <module>
    path('api/', include('dashboard.urls')),
  File "/home/xgrdscpi/virtualenv/api.lulucollection-52.digitaltek.co.in/3.8/lib/python3.8/site-packages/django/urls/conf.py", line 38, in include
    urlconf_module = import_module(urlconf_module)
  File "/opt/alt/python38/lib64/python3.8/importlib/__init__.py", line 127, in import_module
    return _bootstrap._gcd_import(name[level:], package, level)
  File "<frozen importlib._bootstrap>", line 1014, in _gcd_import
  File "<frozen importlib._bootstrap>", line 991, in _find_and_load
  File "<frozen importlib._bootstrap>", line 975, in _find_and_load_unlocked
  File "<frozen importlib._bootstrap>", line 671, in _load_unlocked
  File "<frozen importlib._bootstrap_external>", line 843, in exec_module
  File "<frozen importlib._bootstrap>", line 219, in _call_with_frames_removed
  File "/home/xgrdscpi/api.lulucollection-52.digitaltek.co.in/dashboard/urls.py", line 109, in <module>
    path('about-us/', AboutUsView.as_view(), name='about-us'),
NameError: name 'AboutUsView' is not defined

During handling of the above exception, another exception occurred:

Traceback (most recent call last):
  File "/home/xgrdscpi/virtualenv/api.lulucollection-52.digitaltek.co.in/3.8/lib/python3.8/site-packages/django/core/handlers/exception.py", line 55, in inner
    response = get_response(request)
  File "/home/xgrdscpi/virtualenv/api.lulucollection-52.digitaltek.co.in/3.8/lib/python3.8/site-packages/django/utils/deprecation.py", line 134, in __call__
    response = response or self.get_response(request)
  File "/home/xgrdscpi/virtualenv/api.lulucollection-52.digitaltek.co.in/3.8/lib/python3.8/site-packages/django/core/handlers/exception.py", line 57, in inner
    response = response_for_exception(request, exc)
  File "/home/xgrdscpi/virtualenv/api.lulucollection-52.digitaltek.co.in/3.8/lib/python3.8/site-packages/django/core/handlers/exception.py", line 140, in response_for_exception
    response = handle_uncaught_exception(
  File "/home/xgrdscpi/virtualenv/api.lulucollection-52.digitaltek.co.in/3.8/lib/python3.8/site-packages/django/core/handlers/exception.py", line 184, in handle_uncaught_exception
    callback = resolver.resolve_error_handler(500)
  File "/home/xgrdscpi/virtualenv/api.lulucollection-52.digitaltek.co.in/3.8/lib/python3.8/site-packages/django/urls/resolvers.py", line 729, in resolve_error_handler
    callback = getattr(self.urlconf_module, "handler%s" % view_type, None)
  File "/home/xgrdscpi/virtualenv/api.lulucollection-52.digitaltek.co.in/3.8/lib/python3.8/site-packages/django/utils/functional.py", line 57, in __get__
    res = instance.__dict__[self.name] = self.func(instance)
  File "/home/xgrdscpi/virtualenv/api.lulucollection-52.digitaltek.co.in/3.8/lib/python3.8/site-packages/django/urls/resolvers.py", line 708, in urlconf_module
    return import_module(self.urlconf_name)
  File "/opt/alt/python38/lib64/python3.8/importlib/__init__.py", line 127, in import_module
    return _bootstrap._gcd_import(name[level:], package, level)
  File "<frozen importlib._bootstrap>", line 1014, in _gcd_import
  File "<frozen importlib._bootstrap>", line 991, in _find_and_load
  File "<frozen importlib._bootstrap>", line 975, in _find_and_load_unlocked
  File "<frozen importlib._bootstrap>", line 671, in _load_unlocked
  File "<frozen importlib._bootstrap_external>", line 843, in exec_module
  File "<frozen importlib._bootstrap>", line 219, in _call_with_frames_removed
  File "/home/xgrdscpi/api.lulucollection-52.digitaltek.co.in/backend/urls.py", line 33, in <module>
    path('api/', include('dashboard.urls')),
  File "/home/xgrdscpi/virtualenv/api.lulucollection-52.digitaltek.co.in/3.8/lib/python3.8/site-packages/django/urls/conf.py", line 38, in include
    urlconf_module = import_module(urlconf_module)
  File "/opt/alt/python38/lib64/python3.8/importlib/__init__.py", line 127, in import_module
    return _bootstrap._gcd_import(name[level:], package, level)
  File "<frozen importlib._bootstrap>", line 1014, in _gcd_import
  File "<frozen importlib._bootstrap>", line 991, in _find_and_load
  File "<frozen importlib._bootstrap>", line 975, in _find_and_load_unlocked
  File "<frozen importlib._bootstrap>", line 671, in _load_unlocked
  File "<frozen importlib._bootstrap_external>", line 843, in exec_module
  File "<frozen importlib._bootstrap>", line 219, in _call_with_frames_removed
  File "/home/xgrdscpi/api.lulucollection-52.digitaltek.co.in/dashboard/urls.py", line 109, in <module>
    path('about-us/', AboutUsView.as_view(), name='about-us'),
NameError: name 'AboutUsView' is not defined

During handling of the above exception, another exception occurred:

Traceback (most recent call last):
  File "/home/xgrdscpi/virtualenv/api.lulucollection-52.digitaltek.co.in/3.8/lib/python3.8/site-packages/django/core/handlers/exception.py", line 55, in inner
    response = get_response(request)
  File "/home/xgrdscpi/virtualenv/api.lulucollection-52.digitaltek.co.in/3.8/lib/python3.8/site-packages/django/utils/deprecation.py", line 134, in __call__
    response = response or self.get_response(request)
  File "/home/xgrdscpi/virtualenv/api.lulucollection-52.digitaltek.co.in/3.8/lib/python3.8/site-packages/django/core/handlers/exception.py", line 57, in inner
    response = response_for_exception(request, exc)
  File "/home/xgrdscpi/virtualenv/api.lulucollection-52.digitaltek.co.in/3.8/lib/python3.8/site-packages/django/core/handlers/exception.py", line 140, in response_for_exception
    response = handle_uncaught_exception(
  File "/home/xgrdscpi/virtualenv/api.lulucollection-52.digitaltek.co.in/3.8/lib/python3.8/site-packages/django/core/handlers/exception.py", line 184, in handle_uncaught_exception
    callback = resolver.resolve_error_handler(500)
  File "/home/xgrdscpi/virtualenv/api.lulucollection-52.digitaltek.co.in/3.8/lib/python3.8/site-packages/django/urls/resolvers.py", line 729, in resolve_error_handler
    callback = getattr(self.urlconf_module, "handler%s" % view_type, None)
  File "/home/xgrdscpi/virtualenv/api.lulucollection-52.digitaltek.co.in/3.8/lib/python3.8/site-packages/django/utils/functional.py", line 57, in __get__
    res = instance.__dict__[self.name] = self.func(instance)
  File "/home/xgrdscpi/virtualenv/api.lulucollection-52.digitaltek.co.in/3.8/lib/python3.8/site-packages/django/urls/resolvers.py", line 708, in urlconf_module
    return import_module(self.urlconf_name)
  File "/opt/alt/python38/lib64/python3.8/importlib/__init__.py", line 127, in import_module
    return _bootstrap._gcd_import(name[level:], package, level)
  File "<frozen importlib._bootstrap>", line 1014, in _gcd_import
  File "<frozen importlib._bootstrap>", line 991, in _find_and_load
  File "<frozen importlib._bootstrap>", line 975, in _find_and_load_unlocked
  File "<frozen importlib._bootstrap>", line 671, in _load_unlocked
  File "<frozen importlib._bootstrap_external>", line 843, in exec_module
  File "<frozen importlib._bootstrap>", line 219, in _call_with_frames_removed
  File "/home/xgrdscpi/api.lulucollection-52.digitaltek.co.in/backend/urls.py", line 33, in <module>
    path('api/', include('dashboard.urls')),
  File "/home/xgrdscpi/virtualenv/api.lulucollection-52.digitaltek.co.in/3.8/lib/python3.8/site-packages/django/urls/conf.py", line 38, in include
    urlconf_module = import_module(urlconf_module)
  File "/opt/alt/python38/lib64/python3.8/importlib/__init__.py", line 127, in import_module
    return _bootstrap._gcd_import(name[level:], package, level)
  File "<frozen importlib._bootstrap>", line 1014, in _gcd_import
  File "<frozen importlib._bootstrap>", line 991, in _find_and_load
  File "<frozen importlib._bootstrap>", line 975, in _find_and_load_unlocked
  File "<frozen importlib._bootstrap>", line 671, in _load_unlocked
  File "<frozen importlib._bootstrap_external>", line 843, in exec_module
  File "<frozen importlib._bootstrap>", line 219, in _call_with_frames_removed
  File "/home/xgrdscpi/api.lulucollection-52.digitaltek.co.in/dashboard/urls.py", line 109, in <module>
    path('about-us/', AboutUsView.as_view(), name='about-us'),
NameError: name 'AboutUsView' is not defined

During handling of the above exception, another exception occurred:

Traceback (most recent call last):
  File "/home/xgrdscpi/virtualenv/api.lulucollection-52.digitaltek.co.in/3.8/lib/python3.8/site-packages/django/core/handlers/exception.py", line 55, in inner
    response = get_response(request)
  File "/home/xgrdscpi/virtualenv/api.lulucollection-52.digitaltek.co.in/3.8/lib/python3.8/site-packages/corsheaders/middleware.py", line 56, in __call__
    result = self.get_response(request)
  File "/home/xgrdscpi/virtualenv/api.lulucollection-52.digitaltek.co.in/3.8/lib/python3.8/site-packages/django/core/handlers/exception.py", line 57, in inner
    response = response_for_exception(request, exc)
  File "/home/xgrdscpi/virtualenv/api.lulucollection-52.digitaltek.co.in/3.8/lib/python3.8/site-packages/django/core/handlers/exception.py", line 140, in response_for_exception
    response = handle_uncaught_exception(
  File "/home/xgrdscpi/virtualenv/api.lulucollection-52.digitaltek.co.in/3.8/lib/python3.8/site-packages/django/core/handlers/exception.py", line 184, in handle_uncaught_exception
    callback = resolver.resolve_error_handler(500)
  File "/home/xgrdscpi/virtualenv/api.lulucollection-52.digitaltek.co.in/3.8/lib/python3.8/site-packages/django/urls/resolvers.py", line 729, in resolve_error_handler
    callback = getattr(self.urlconf_module, "handler%s" % view_type, None)
  File "/home/xgrdscpi/virtualenv/api.lulucollection-52.digitaltek.co.in/3.8/lib/python3.8/site-packages/django/utils/functional.py", line 57, in __get__
    res = instance.__dict__[self.name] = self.func(instance)
  File "/home/xgrdscpi/virtualenv/api.lulucollection-52.digitaltek.co.in/3.8/lib/python3.8/site-packages/django/urls/resolvers.py", line 708, in urlconf_module
    return import_module(self.urlconf_name)
  File "/opt/alt/python38/lib64/python3.8/importlib/__init__.py", line 127, in import_module
    return _bootstrap._gcd_import(name[level:], package, level)
  File "<frozen importlib._bootstrap>", line 1014, in _gcd_import
  File "<frozen importlib._bootstrap>", line 991, in _find_and_load
  File "<frozen importlib._bootstrap>", line 975, in _find_and_load_unlocked
  File "<frozen importlib._bootstrap>", line 671, in _load_unlocked
  File "<frozen importlib._bootstrap_external>", line 843, in exec_module
  File "<frozen importlib._bootstrap>", line 219, in _call_with_frames_removed
  File "/home/xgrdscpi/api.lulucollection-52.digitaltek.co.in/backend/urls.py", line 33, in <module>
    path('api/', include('dashboard.urls')),
  File "/home/xgrdscpi/virtualenv/api.lulucollection-52.digitaltek.co.in/3.8/lib/python3.8/site-packages/django/urls/conf.py", line 38, in include
    urlconf_module = import_module(urlconf_module)
  File "/opt/alt/python38/lib64/python3.8/importlib/__init__.py", line 127, in import_module
    return _bootstrap._gcd_import(name[level:], package, level)
  File "<frozen importlib._bootstrap>", line 1014, in _gcd_import
  File "<frozen importlib._bootstrap>", line 991, in _find_and_load
  File "<frozen importlib._bootstrap>", line 975, in _find_and_load_unlocked
  File "<frozen importlib._bootstrap>", line 671, in _load_unlocked
  File "<frozen importlib._bootstrap_external>", line 843, in exec_module
  File "<frozen importlib._bootstrap>", line 219, in _call_with_frames_removed
  File "/home/xgrdscpi/api.lulucollection-52.digitaltek.co.in/dashboard/urls.py", line 109, in <module>
    path('about-us/', AboutUsView.as_view(), name='about-us'),
NameError: name 'AboutUsView' is not defined

During handling of the above exception, another exception occurred:

Traceback (most recent call last):
  File "/home/xgrdscpi/virtualenv/api.lulucollection-52.digitaltek.co.in/3.8/lib/python3.8/site-packages/django/core/handlers/exception.py", line 55, in inner
    response = get_response(request)
  File "/home/xgrdscpi/virtualenv/api.lulucollection-52.digitaltek.co.in/3.8/lib/python3.8/site-packages/django/utils/deprecation.py", line 134, in __call__
    response = response or self.get_response(request)
  File "/home/xgrdscpi/virtualenv/api.lulucollection-52.digitaltek.co.in/3.8/lib/python3.8/site-packages/django/core/handlers/exception.py", line 57, in inner
    response = response_for_exception(request, exc)
  File "/home/xgrdscpi/virtualenv/api.lulucollection-52.digitaltek.co.in/3.8/lib/python3.8/site-packages/django/core/handlers/exception.py", line 140, in response_for_exception
    response = handle_uncaught_exception(
  File "/home/xgrdscpi/virtualenv/api.lulucollection-52.digitaltek.co.in/3.8/lib/python3.8/site-packages/django/core/handlers/exception.py", line 184, in handle_uncaught_exception
    callback = resolver.resolve_error_handler(500)
  File "/home/xgrdscpi/virtualenv/api.lulucollection-52.digitaltek.co.in/3.8/lib/python3.8/site-packages/django/urls/resolvers.py", line 729, in resolve_error_handler
    callback = getattr(self.urlconf_module, "handler%s" % view_type, None)
  File "/home/xgrdscpi/virtualenv/api.lulucollection-52.digitaltek.co.in/3.8/lib/python3.8/site-packages/django/utils/functional.py", line 57, in __get__
    res = instance.__dict__[self.name] = self.func(instance)
  File "/home/xgrdscpi/virtualenv/api.lulucollection-52.digitaltek.co.in/3.8/lib/python3.8/site-packages/django/urls/resolvers.py", line 708, in urlconf_module
    return import_module(self.urlconf_name)
  File "/opt/alt/python38/lib64/python3.8/importlib/__init__.py", line 127, in import_module
    return _bootstrap._gcd_import(name[level:], package, level)
  File "<frozen importlib._bootstrap>", line 1014, in _gcd_import
  File "<frozen importlib._bootstrap>", line 991, in _find_and_load
  File "<frozen importlib._bootstrap>", line 975, in _find_and_load_unlocked
  File "<frozen importlib._bootstrap>", line 671, in _load_unlocked
  File "<frozen importlib._bootstrap_external>", line 843, in exec_module
  File "<frozen importlib._bootstrap>", line 219, in _call_with_frames_removed
  File "/home/xgrdscpi/api.lulucollection-52.digitaltek.co.in/backend/urls.py", line 33, in <module>
    path('api/', include('dashboard.urls')),
  File "/home/xgrdscpi/virtualenv/api.lulucollection-52.digitaltek.co.in/3.8/lib/python3.8/site-packages/django/urls/conf.py", line 38, in include
    urlconf_module = import_module(urlconf_module)
  File "/opt/alt/python38/lib64/python3.8/importlib/__init__.py", line 127, in import_module
    return _bootstrap._gcd_import(name[level:], package, level)
  File "<frozen importlib._bootstrap>", line 1014, in _gcd_import
  File "<frozen importlib._bootstrap>", line 991, in _find_and_load
  File "<frozen importlib._bootstrap>", line 975, in _find_and_load_unlocked
  File "<frozen importlib._bootstrap>", line 671, in _load_unlocked
  File "<frozen importlib._bootstrap_external>", line 843, in exec_module
  File "<frozen importlib._bootstrap>", line 219, in _call_with_frames_removed
  File "/home/xgrdscpi/api.lulucollection-52.digitaltek.co.in/dashboard/urls.py", line 109, in <module>
    path('about-us/', AboutUsView.as_view(), name='about-us'),
NameError: name 'AboutUsView' is not defined

During handling of the above exception, another exception occurred:

Traceback (most recent call last):
  File "/home/xgrdscpi/virtualenv/api.lulucollection-52.digitaltek.co.in/3.8/lib/python3.8/site-packages/django/core/handlers/exception.py", line 55, in inner
    response = get_response(request)
  File "/home/xgrdscpi/virtualenv/api.lulucollection-52.digitaltek.co.in/3.8/lib/python3.8/site-packages/django/utils/deprecation.py", line 134, in __call__
    response = response or self.get_response(request)
  File "/home/xgrdscpi/virtualenv/api.lulucollection-52.digitaltek.co.in/3.8/lib/python3.8/site-packages/django/core/handlers/exception.py", line 57, in inner
    response = response_for_exception(request, exc)
  File "/home/xgrdscpi/virtualenv/api.lulucollection-52.digitaltek.co.in/3.8/lib/python3.8/site-packages/django/core/handlers/exception.py", line 140, in response_for_exception
    response = handle_uncaught_exception(
  File "/home/xgrdscpi/virtualenv/api.lulucollection-52.digitaltek.co.in/3.8/lib/python3.8/site-packages/django/core/handlers/exception.py", line 184, in handle_uncaught_exception
    callback = resolver.resolve_error_handler(500)
  File "/home/xgrdscpi/virtualenv/api.lulucollection-52.digitaltek.co.in/3.8/lib/python3.8/site-packages/django/urls/resolvers.py", line 729, in resolve_error_handler
    callback = getattr(self.urlconf_module, "handler%s" % view_type, None)
  File "/home/xgrdscpi/virtualenv/api.lulucollection-52.digitaltek.co.in/3.8/lib/python3.8/site-packages/django/utils/functional.py", line 57, in __get__
    res = instance.__dict__[self.name] = self.func(instance)
  File "/home/xgrdscpi/virtualenv/api.lulucollection-52.digitaltek.co.in/3.8/lib/python3.8/site-packages/django/urls/resolvers.py", line 708, in urlconf_module
    return import_module(self.urlconf_name)
  File "/opt/alt/python38/lib64/python3.8/importlib/__init__.py", line 127, in import_module
    return _bootstrap._gcd_import(name[level:], package, level)
  File "<frozen importlib._bootstrap>", line 1014, in _gcd_import
  File "<frozen importlib._bootstrap>", line 991, in _find_and_load
  File "<frozen importlib._bootstrap>", line 975, in _find_and_load_unlocked
  File "<frozen importlib._bootstrap>", line 671, in _load_unlocked
  File "<frozen importlib._bootstrap_external>", line 843, in exec_module
  File "<frozen importlib._bootstrap>", line 219, in _call_with_frames_removed
  File "/home/xgrdscpi/api.lulucollection-52.digitaltek.co.in/backend/urls.py", line 33, in <module>
    path('api/', include('dashboard.urls')),
  File "/home/xgrdscpi/virtualenv/api.lulucollection-52.digitaltek.co.in/3.8/lib/python3.8/site-packages/django/urls/conf.py", line 38, in include
    urlconf_module = import_module(urlconf_module)
  File "/opt/alt/python38/lib64/python3.8/importlib/__init__.py", line 127, in import_module
    return _bootstrap._gcd_import(name[level:], package, level)
  File "<frozen importlib._bootstrap>", line 1014, in _gcd_import
  File "<frozen importlib._bootstrap>", line 991, in _find_and_load
  File "<frozen importlib._bootstrap>", line 975, in _find_and_load_unlocked
  File "<frozen importlib._bootstrap>", line 671, in _load_unlocked
  File "<frozen importlib._bootstrap_external>", line 843, in exec_module
  File "<frozen importlib._bootstrap>", line 219, in _call_with_frames_removed
  File "/home/xgrdscpi/api.lulucollection-52.digitaltek.co.in/dashboard/urls.py", line 109, in <module>
    path('about-us/', AboutUsView.as_view(), name='about-us'),
NameError: name 'AboutUsView' is not defined

During handling of the above exception, another exception occurred:

Traceback (most recent call last):
  File "/home/xgrdscpi/virtualenv/api.lulucollection-52.digitaltek.co.in/3.8/lib/python3.8/site-packages/django/core/handlers/wsgi.py", line 124, in __call__
    response = self.get_response(request)
  File "/home/xgrdscpi/virtualenv/api.lulucollection-52.digitaltek.co.in/3.8/lib/python3.8/site-packages/django/core/handlers/base.py", line 140, in get_response
    response = self._middleware_chain(request)
  File "/home/xgrdscpi/virtualenv/api.lulucollection-52.digitaltek.co.in/3.8/lib/python3.8/site-packages/django/core/handlers/exception.py", line 57, in inner
    response = response_for_exception(request, exc)
  File "/home/xgrdscpi/virtualenv/api.lulucollection-52.digitaltek.co.in/3.8/lib/python3.8/site-packages/django/core/handlers/exception.py", line 140, in response_for_exception
    response = handle_uncaught_exception(
  File "/home/xgrdscpi/virtualenv/api.lulucollection-52.digitaltek.co.in/3.8/lib/python3.8/site-packages/django/core/handlers/exception.py", line 184, in handle_uncaught_exception
    callback = resolver.resolve_error_handler(500)
  File "/home/xgrdscpi/virtualenv/api.lulucollection-52.digitaltek.co.in/3.8/lib/python3.8/site-packages/django/urls/resolvers.py", line 729, in resolve_error_handler
    callback = getattr(self.urlconf_module, "handler%s" % view_type, None)
  File "/home/xgrdscpi/virtualenv/api.lulucollection-52.digitaltek.co.in/3.8/lib/python3.8/site-packages/django/utils/functional.py", line 57, in __get__
    res = instance.__dict__[self.name] = self.func(instance)
  File "/home/xgrdscpi/virtualenv/api.lulucollection-52.digitaltek.co.in/3.8/lib/python3.8/site-packages/django/urls/resolvers.py", line 708, in urlconf_module
    return import_module(self.urlconf_name)
  File "/opt/alt/python38/lib64/python3.8/importlib/__init__.py", line 127, in import_module
    return _bootstrap._gcd_import(name[level:], package, level)
  File "<frozen importlib._bootstrap>", line 1014, in _gcd_import
  File "<frozen importlib._bootstrap>", line 991, in _find_and_load
  File "<frozen importlib._bootstrap>", line 975, in _find_and_load_unlocked
  File "<frozen importlib._bootstrap>", line 671, in _load_unlocked
  File "<frozen importlib._bootstrap_external>", line 843, in exec_module
  File "<frozen importlib._bootstrap>", line 219, in _call_with_frames_removed
  File "/home/xgrdscpi/api.lulucollection-52.digitaltek.co.in/backend/urls.py", line 33, in <module>
    path('api/', include('dashboard.urls')),
  File "/home/xgrdscpi/virtualenv/api.lulucollection-52.digitaltek.co.in/3.8/lib/python3.8/site-packages/django/urls/conf.py", line 38, in include
    urlconf_module = import_module(urlconf_module)
  File "/opt/alt/python38/lib64/python3.8/importlib/__init__.py", line 127, in import_module
    return _bootstrap._gcd_import(name[level:], package, level)
  File "<frozen importlib._bootstrap>", line 1014, in _gcd_import
  File "<frozen importlib._bootstrap>", line 991, in _find_and_load
  File "<frozen importlib._bootstrap>", line 975, in _find_and_load_unlocked
  File "<frozen importlib._bootstrap>", line 671, in _load_unlocked
  File "<frozen importlib._bootstrap_external>", line 843, in exec_module
  File "<frozen importlib._bootstrap>", line 219, in _call_with_frames_removed
  File "/home/xgrdscpi/api.lulucollection-52.digitaltek.co.in/dashboard/urls.py", line 109, in <module>
    path('about-us/', AboutUsView.as_view(), name='about-us'),
NameError: name 'AboutUsView' is not defined
Traceback (most recent call last):
  File "/home/xgrdscpi/api.lulucollection-52.digitaltek.co.in/passenger_wsgi.py", line 4, in <module>
    from backend.wsgi import application
  File "/home/xgrdscpi/api.lulucollection-52.digitaltek.co.in/backend/wsgi.py", line 16, in <module>
    application = get_wsgi_application()
  File "/home/xgrdscpi/virtualenv/api.lulucollection-52.digitaltek.co.in/3.8/lib/python3.8/site-packages/django/core/wsgi.py", line 12, in get_wsgi_application
    django.setup(set_prefix=False)
  File "/home/xgrdscpi/virtualenv/api.lulucollection-52.digitaltek.co.in/3.8/lib/python3.8/site-packages/django/__init__.py", line 19, in setup
    configure_logging(settings.LOGGING_CONFIG, settings.LOGGING)
  File "/home/xgrdscpi/virtualenv/api.lulucollection-52.digitaltek.co.in/3.8/lib/python3.8/site-packages/django/conf/__init__.py", line 102, in __getattr__
    self._setup(name)
  File "/home/xgrdscpi/virtualenv/api.lulucollection-52.digitaltek.co.in/3.8/lib/python3.8/site-packages/django/conf/__init__.py", line 89, in _setup
    self._wrapped = Settings(settings_module)
  File "/home/xgrdscpi/virtualenv/api.lulucollection-52.digitaltek.co.in/3.8/lib/python3.8/site-packages/django/conf/__init__.py", line 217, in __init__
    mod = importlib.import_module(self.SETTINGS_MODULE)
  File "/opt/alt/python38/lib64/python3.8/importlib/__init__.py", line 127, in import_module
    return _bootstrap._gcd_import(name[level:], package, level)
  File "/home/xgrdscpi/api.lulucollection-52.digitaltek.co.in/backend/settings.py", line 157
    'https://lulucollection-52.digitaltek.co.in
                                              ^
SyntaxError: EOL while scanning string literal
Traceback (most recent call last):
  File "/home/xgrdscpi/api.lulucollection-52.digitaltek.co.in/passenger_wsgi.py", line 4, in <module>
    from backend.wsgi import application
  File "/home/xgrdscpi/api.lulucollection-52.digitaltek.co.in/backend/wsgi.py", line 16, in <module>
    application = get_wsgi_application()
  File "/home/xgrdscpi/virtualenv/api.lulucollection-52.digitaltek.co.in/3.8/lib/python3.8/site-packages/django/core/wsgi.py", line 12, in get_wsgi_application
    django.setup(set_prefix=False)
  File "/home/xgrdscpi/virtualenv/api.lulucollection-52.digitaltek.co.in/3.8/lib/python3.8/site-packages/django/__init__.py", line 19, in setup
    configure_logging(settings.LOGGING_CONFIG, settings.LOGGING)
  File "/home/xgrdscpi/virtualenv/api.lulucollection-52.digitaltek.co.in/3.8/lib/python3.8/site-packages/django/conf/__init__.py", line 102, in __getattr__
    self._setup(name)
  File "/home/xgrdscpi/virtualenv/api.lulucollection-52.digitaltek.co.in/3.8/lib/python3.8/site-packages/django/conf/__init__.py", line 89, in _setup
    self._wrapped = Settings(settings_module)
  File "/home/xgrdscpi/virtualenv/api.lulucollection-52.digitaltek.co.in/3.8/lib/python3.8/site-packages/django/conf/__init__.py", line 217, in __init__
    mod = importlib.import_module(self.SETTINGS_MODULE)
  File "/opt/alt/python38/lib64/python3.8/importlib/__init__.py", line 127, in import_module
    return _bootstrap._gcd_import(name[level:], package, level)
  File "/home/xgrdscpi/api.lulucollection-52.digitaltek.co.in/backend/settings.py", line 157
    'https://lulucollection-52.digitaltek.co.in
                                              ^
SyntaxError: EOL while scanning string literal
[UID:4986][3763765] Child process with pid: 3763883 was killed by signal: 15, core dump: 0
Traceback (most recent call last):
  File "/home/xgrdscpi/api.lulucollection-52.digitaltek.co.in/passenger_wsgi.py", line 4, in <module>
    from backend.wsgi import application
  File "/home/xgrdscpi/api.lulucollection-52.digitaltek.co.in/backend/wsgi.py", line 16, in <module>
    application = get_wsgi_application()
  File "/home/xgrdscpi/virtualenv/api.lulucollection-52.digitaltek.co.in/3.8/lib/python3.8/site-packages/django/core/wsgi.py", line 12, in get_wsgi_application
    django.setup(set_prefix=False)
  File "/home/xgrdscpi/virtualenv/api.lulucollection-52.digitaltek.co.in/3.8/lib/python3.8/site-packages/django/__init__.py", line 19, in setup
    configure_logging(settings.LOGGING_CONFIG, settings.LOGGING)
  File "/home/xgrdscpi/virtualenv/api.lulucollection-52.digitaltek.co.in/3.8/lib/python3.8/site-packages/django/conf/__init__.py", line 102, in __getattr__
    self._setup(name)
  File "/home/xgrdscpi/virtualenv/api.lulucollection-52.digitaltek.co.in/3.8/lib/python3.8/site-packages/django/conf/__init__.py", line 89, in _setup
    self._wrapped = Settings(settings_module)
  File "/home/xgrdscpi/virtualenv/api.lulucollection-52.digitaltek.co.in/3.8/lib/python3.8/site-packages/django/conf/__init__.py", line 217, in __init__
    mod = importlib.import_module(self.SETTINGS_MODULE)
  File "/opt/alt/python38/lib64/python3.8/importlib/__init__.py", line 127, in import_module
    return _bootstrap._gcd_import(name[level:], package, level)
  File "/home/xgrdscpi/api.lulucollection-52.digitaltek.co.in/backend/settings.py", line 157
    'https://lulucollection-52.digitaltek.co.in
                                              ^
SyntaxError: EOL while scanning string literal
[UID:4986][3763765] Child process with pid: 3764725 was killed by signal: 15, core dump: 0
Traceback (most recent call last):
  File "/home/xgrdscpi/api.lulucollection-52.digitaltek.co.in/passenger_wsgi.py", line 4, in <module>
    from backend.wsgi import application
  File "/home/xgrdscpi/api.lulucollection-52.digitaltek.co.in/backend/wsgi.py", line 16, in <module>
    application = get_wsgi_application()
  File "/home/xgrdscpi/virtualenv/api.lulucollection-52.digitaltek.co.in/3.8/lib/python3.8/site-packages/django/core/wsgi.py", line 12, in get_wsgi_application
    django.setup(set_prefix=False)
  File "/home/xgrdscpi/virtualenv/api.lulucollection-52.digitaltek.co.in/3.8/lib/python3.8/site-packages/django/__init__.py", line 19, in setup
    configure_logging(settings.LOGGING_CONFIG, settings.LOGGING)
  File "/home/xgrdscpi/virtualenv/api.lulucollection-52.digitaltek.co.in/3.8/lib/python3.8/site-packages/django/conf/__init__.py", line 102, in __getattr__
    self._setup(name)
  File "/home/xgrdscpi/virtualenv/api.lulucollection-52.digitaltek.co.in/3.8/lib/python3.8/site-packages/django/conf/__init__.py", line 89, in _setup
    self._wrapped = Settings(settings_module)
  File "/home/xgrdscpi/virtualenv/api.lulucollection-52.digitaltek.co.in/3.8/lib/python3.8/site-packages/django/conf/__init__.py", line 217, in __init__
    mod = importlib.import_module(self.SETTINGS_MODULE)
  File "/opt/alt/python38/lib64/python3.8/importlib/__init__.py", line 127, in import_module
    return _bootstrap._gcd_import(name[level:], package, level)
  File "/home/xgrdscpi/api.lulucollection-52.digitaltek.co.in/backend/settings.py", line 157
    'https://lulucollection-52.digitaltek.co.in
                                              ^
SyntaxError: EOL while scanning string literal
[UID:4986][3763765] Child process with pid: 3764843 was killed by signal: 15, core dump: 0
Traceback (most recent call last):
  File "/home/xgrdscpi/api.lulucollection-52.digitaltek.co.in/passenger_wsgi.py", line 4, in <module>
    from backend.wsgi import application
  File "/home/xgrdscpi/api.lulucollection-52.digitaltek.co.in/backend/wsgi.py", line 16, in <module>
    application = get_wsgi_application()
  File "/home/xgrdscpi/virtualenv/api.lulucollection-52.digitaltek.co.in/3.8/lib/python3.8/site-packages/django/core/wsgi.py", line 12, in get_wsgi_application
    django.setup(set_prefix=False)
  File "/home/xgrdscpi/virtualenv/api.lulucollection-52.digitaltek.co.in/3.8/lib/python3.8/site-packages/django/__init__.py", line 19, in setup
    configure_logging(settings.LOGGING_CONFIG, settings.LOGGING)
  File "/home/xgrdscpi/virtualenv/api.lulucollection-52.digitaltek.co.in/3.8/lib/python3.8/site-packages/django/conf/__init__.py", line 102, in __getattr__
    self._setup(name)
  File "/home/xgrdscpi/virtualenv/api.lulucollection-52.digitaltek.co.in/3.8/lib/python3.8/site-packages/django/conf/__init__.py", line 89, in _setup
    self._wrapped = Settings(settings_module)
  File "/home/xgrdscpi/virtualenv/api.lulucollection-52.digitaltek.co.in/3.8/lib/python3.8/site-packages/django/conf/__init__.py", line 217, in __init__
    mod = importlib.import_module(self.SETTINGS_MODULE)
  File "/opt/alt/python38/lib64/python3.8/importlib/__init__.py", line 127, in import_module
    return _bootstrap._gcd_import(name[level:], package, level)
  File "/home/xgrdscpi/api.lulucollection-52.digitaltek.co.in/backend/settings.py", line 157
    'https://lulucollection-52.digitaltek.co.in
                                              ^
SyntaxError: EOL while scanning string literal
[UID:4986][3763765] Child process with pid: 3766327 was killed by signal: 15, core dump: 0
Error blacklisting refresh token: Token is blacklisted
[UID:4986][979313] Child process with pid: 1126275 was killed by signal: 15, core dump: 0
Error blacklisting refresh token: Token is blacklisted
Internal Server Error: /api/add_to_cart/20/
Traceback (most recent call last):
  File "/home/xgrdscpi/virtualenv/api.lulucollection-52.digitaltek.co.in/3.8/lib/python3.8/site-packages/django/db/models/query.py", line 916, in get_or_create
    return self.get(**kwargs), False
  File "/home/xgrdscpi/virtualenv/api.lulucollection-52.digitaltek.co.in/3.8/lib/python3.8/site-packages/django/db/models/query.py", line 637, in get
    raise self.model.DoesNotExist(
api.models.Cart.DoesNotExist: Cart matching query does not exist.

During handling of the above exception, another exception occurred:

Traceback (most recent call last):
  File "/home/xgrdscpi/virtualenv/api.lulucollection-52.digitaltek.co.in/3.8/lib/python3.8/site-packages/django/db/backends/utils.py", line 89, in _execute
    return self.cursor.execute(sql, params)
  File "/home/xgrdscpi/virtualenv/api.lulucollection-52.digitaltek.co.in/3.8/lib/python3.8/site-packages/django/db/backends/sqlite3/base.py", line 328, in execute
    return super().execute(query, params)
sqlite3.IntegrityError: UNIQUE constraint failed: api_cart.slug

The above exception was the direct cause of the following exception:

Traceback (most recent call last):
  File "/home/xgrdscpi/virtualenv/api.lulucollection-52.digitaltek.co.in/3.8/lib/python3.8/site-packages/django/core/handlers/exception.py", line 55, in inner
    response = get_response(request)
  File "/home/xgrdscpi/virtualenv/api.lulucollection-52.digitaltek.co.in/3.8/lib/python3.8/site-packages/django/core/handlers/base.py", line 197, in _get_response
    response = wrapped_callback(request, *callback_args, **callback_kwargs)
  File "/home/xgrdscpi/virtualenv/api.lulucollection-52.digitaltek.co.in/3.8/lib/python3.8/site-packages/django/views/decorators/csrf.py", line 56, in wrapper_view
    return view_func(*args, **kwargs)
  File "/home/xgrdscpi/virtualenv/api.lulucollection-52.digitaltek.co.in/3.8/lib/python3.8/site-packages/django/views/generic/base.py", line 104, in view
    return self.dispatch(request, *args, **kwargs)
  File "/home/xgrdscpi/virtualenv/api.lulucollection-52.digitaltek.co.in/3.8/lib/python3.8/site-packages/rest_framework/views.py", line 509, in dispatch
    response = self.handle_exception(exc)
  File "/home/xgrdscpi/virtualenv/api.lulucollection-52.digitaltek.co.in/3.8/lib/python3.8/site-packages/rest_framework/views.py", line 469, in handle_exception
    self.raise_uncaught_exception(exc)
  File "/home/xgrdscpi/virtualenv/api.lulucollection-52.digitaltek.co.in/3.8/lib/python3.8/site-packages/rest_framework/views.py", line 480, in raise_uncaught_exception
    raise exc
  File "/home/xgrdscpi/virtualenv/api.lulucollection-52.digitaltek.co.in/3.8/lib/python3.8/site-packages/rest_framework/views.py", line 506, in dispatch
    response = handler(request, *args, **kwargs)
  File "/home/xgrdscpi/api.lulucollection-52.digitaltek.co.in/dashboard/views.py", line 214, in post
    cart, created = Cart.objects.get_or_create(user=user)
  File "/home/xgrdscpi/virtualenv/api.lulucollection-52.digitaltek.co.in/3.8/lib/python3.8/site-packages/django/db/models/manager.py", line 87, in manager_method
    return getattr(self.get_queryset(), name)(*args, **kwargs)
  File "/home/xgrdscpi/virtualenv/api.lulucollection-52.digitaltek.co.in/3.8/lib/python3.8/site-packages/django/db/models/query.py", line 923, in get_or_create
    return self.create(**params), True
  File "/home/xgrdscpi/virtualenv/api.lulucollection-52.digitaltek.co.in/3.8/lib/python3.8/site-packages/django/db/models/query.py", line 658, in create
    obj.save(force_insert=True, using=self.db)
  File "/home/xgrdscpi/api.lulucollection-52.digitaltek.co.in/api/models.py", line 90, in save
    super().save(*args, **kwargs)
  File "/home/xgrdscpi/virtualenv/api.lulucollection-52.digitaltek.co.in/3.8/lib/python3.8/site-packages/django/db/models/base.py", line 814, in save
    self.save_base(
  File "/home/xgrdscpi/virtualenv/api.lulucollection-52.digitaltek.co.in/3.8/lib/python3.8/site-packages/django/db/models/base.py", line 877, in save_base
    updated = self._save_table(
  File "/home/xgrdscpi/virtualenv/api.lulucollection-52.digitaltek.co.in/3.8/lib/python3.8/site-packages/django/db/models/base.py", line 1020, in _save_table
    results = self._do_insert(
  File "/home/xgrdscpi/virtualenv/api.lulucollection-52.digitaltek.co.in/3.8/lib/python3.8/site-packages/django/db/models/base.py", line 1061, in _do_insert
    return manager._insert(
  File "/home/xgrdscpi/virtualenv/api.lulucollection-52.digitaltek.co.in/3.8/lib/python3.8/site-packages/django/db/models/manager.py", line 87, in manager_method
    return getattr(self.get_queryset(), name)(*args, **kwargs)
  File "/home/xgrdscpi/virtualenv/api.lulucollection-52.digitaltek.co.in/3.8/lib/python3.8/site-packages/django/db/models/query.py", line 1805, in _insert
    return query.get_compiler(using=using).execute_sql(returning_fields)
  File "/home/xgrdscpi/virtualenv/api.lulucollection-52.digitaltek.co.in/3.8/lib/python3.8/site-packages/django/db/models/sql/compiler.py", line 1820, in execute_sql
    cursor.execute(sql, params)
  File "/home/xgrdscpi/virtualenv/api.lulucollection-52.digitaltek.co.in/3.8/lib/python3.8/site-packages/django/db/backends/utils.py", line 102, in execute
    return super().execute(sql, params)
  File "/home/xgrdscpi/virtualenv/api.lulucollection-52.digitaltek.co.in/3.8/lib/python3.8/site-packages/django/db/backends/utils.py", line 67, in execute
    return self._execute_with_wrappers(
  File "/home/xgrdscpi/virtualenv/api.lulucollection-52.digitaltek.co.in/3.8/lib/python3.8/site-packages/django/db/backends/utils.py", line 80, in _execute_with_wrappers
    return executor(sql, params, many, context)
  File "/home/xgrdscpi/virtualenv/api.lulucollection-52.digitaltek.co.in/3.8/lib/python3.8/site-packages/django/db/backends/utils.py", line 89, in _execute
    return self.cursor.execute(sql, params)
  File "/home/xgrdscpi/virtualenv/api.lulucollection-52.digitaltek.co.in/3.8/lib/python3.8/site-packages/django/db/utils.py", line 91, in __exit__
    raise dj_exc_value.with_traceback(traceback) from exc_value
  File "/home/xgrdscpi/virtualenv/api.lulucollection-52.digitaltek.co.in/3.8/lib/python3.8/site-packages/django/db/backends/utils.py", line 89, in _execute
    return self.cursor.execute(sql, params)
  File "/home/xgrdscpi/virtualenv/api.lulucollection-52.digitaltek.co.in/3.8/lib/python3.8/site-packages/django/db/backends/sqlite3/base.py", line 328, in execute
    return super().execute(query, params)
django.db.utils.IntegrityError: UNIQUE constraint failed: api_cart.slug
Unauthorized: /api/admin/list/product/
Unauthorized: /api/admin/list/product/
Not Found: /favicon.ico
Unauthorized: /api/product/glass-beads/
Unauthorized: /api/products/glass-beads/reviews/
Unauthorized: /api/user/profile/
Unauthorized: /api/homepage/
Unauthorized: /api/user/profile/
Bad Request: /api/token/refresh/
[UID:4986][2717098] Child process with pid: 2719906 was killed by signal: 15, core dump: 0
Unauthorized: /api/homepage/
Forbidden: /api/list/category/
Forbidden: /api/list/category/
Forbidden: /api/admin/list/product/
Forbidden: /api/list/order/
Unauthorized: /api/list/category/
Unauthorized: /api/list/category/
Not Found: /admin/dashboard/
Not Found: /favicon.ico
Unauthorized: /api/list/category/
Unauthorized: /api/list/category/
Unauthorized: /api/list/category/
Unauthorized: /api/list/category/
Unauthorized: /api/admin/list/product/
Unauthorized: /api/admin/list/product/
Unauthorized: /api/admin/list/product/
Unauthorized: /api/user/profile/
Unauthorized: /api/user/profile/
Unauthorized: /api/token/
Bad Request: /api/token/refresh/
Unauthorized: /api/homepage/
Bad Request: /api/token/blacklist/
Error blacklisting refresh token: Token is blacklisted
[UID:4986][3081387] Child process with pid: 3244408 was killed by signal: 15, core dump: 0
Unauthorized: /api/list/category/
Unauthorized: /api/list/category/
Forbidden: /api/list/category/
Forbidden: /api/list/category/
Forbidden: /api/list/category/
Forbidden: /api/list/category/
Forbidden: /api/list/category/
Forbidden: /api/list/category/
Unauthorized: /api/admin/list/product/
Bad Request: /api/token/blacklist/
Unauthorized: /api/token/blacklist/
Unauthorized: /api/token/blacklist/
Error blacklisting refresh token: Token is blacklisted
Unauthorized: /api/user/profile/
Unauthorized: /api/user/profile/
Unauthorized: /api/list/order/
Unauthorized: /api/list/order/
Bad Request: /api/token/refresh/
Bad Request: /api/token/refresh/
Unauthorized: /api/admin/list/product/
Unauthorized: /api/admin/list/product/
Bad Request: /api/token/refresh/
Bad Request: /api/token/refresh/
Unauthorized: /api/list/category/
Unauthorized: /api/list/category/
Bad Request: /api/token/refresh/
Bad Request: /api/token/refresh/
Unauthorized: /api/admin/list/product/
Unauthorized: /api/admin/list/product/
Bad Request: /api/token/refresh/
Bad Request: /api/token/refresh/
Unauthorized: /api/admin/list/product/
Unauthorized: /api/admin/list/product/
Bad Request: /api/token/refresh/
Bad Request: /api/token/refresh/
Unauthorized: /api/list/category/
Unauthorized: /api/list/category/
Bad Request: /api/token/refresh/
Bad Request: /api/token/refresh/
Unauthorized: /api/list/category/
Unauthorized: /api/user/profile/
Unauthorized: /api/list/category/
Bad Request: /api/token/refresh/
Unauthorized: /api/user/profile/
Bad Request: /api/token/refresh/
Bad Request: /api/token/refresh/
Bad Request: /api/token/refresh/
Unauthorized: /api/token/blacklist/
Unauthorized: /api/token/blacklist/
Unauthorized: /api/user/profile/
Unauthorized: /api/user/profile/
Bad Request: /api/token/refresh/
Bad Request: /api/token/refresh/
Unauthorized: /api/admin/list/product/
Unauthorized: /api/admin/list/product/
Bad Request: /api/token/refresh/
Bad Request: /api/token/refresh/
Unauthorized: /api/user/profile/
Unauthorized: /api/user/profile/
Bad Request: /api/token/refresh/
Bad Request: /api/token/refresh/
Forbidden: /api/list/order/
Forbidden: /api/list/order/
Unauthorized: /api/user/profile/
Unauthorized: /api/user/profile/
Unauthorized: /api/user/profile/
Unauthorized: /api/user/profile/
Unauthorized: /api/user/profile/
Unauthorized: /api/user/profile/
Unauthorized: /api/user/profile/
Unauthorized: /api/user/profile/
Bad Request: /api/token/refresh/
Unauthorized: /api/user/profile/
Bad Request: /api/token/refresh/
Unauthorized: /api/user/profile/
Bad Request: /api/token/refresh/
Unauthorized: /api/user/profile/
Unauthorized: /api/user/profile/
Bad Request: /api/token/refresh/
Unauthorized: /api/homepage/
Unauthorized: /api/user/profile/
Unauthorized: /api/user/profile/
Bad Request: /api/token/refresh/
Unauthorized: /api/user/profile/
Bad Request: /api/token/refresh/
Unauthorized: /api/user/profile/
Not Found: /
Not Found: /
Not Found: /
Not Found: /
Not Found: /
Not Found: /
Not Found: /
Not Found: /
Not Found: /
Unauthorized: /api/user/profile/
Bad Request: /api/token/refresh/
Unauthorized: /api/user/profile/
Bad Request: /api/token/refresh/
Unauthorized: /api/user/profile/
Bad Request: /api/token/refresh/
Unauthorized: /api/user/profile/
Bad Request: /api/token/refresh/
Unauthorized: /api/user/profile/
Bad Request: /api/token/refresh/
Unauthorized: /api/user/profile/
Bad Request: /api/token/refresh/
Not Found: /
Not Found: /
Not Found: /
Not Found: /
Unauthorized: /api/user/profile/
Bad Request: /api/token/refresh/
OSError: LSAPI: Socket read/write error
Not Found: /
Not Found: /
Not Found: /
Not Found: /
Not Found: /
Not Found: /
Not Found: /
Not Found: /
Unauthorized: /api/user/profile/
Bad Request: /api/token/refresh/
Unauthorized: /api/user/profile/
Bad Request: /api/token/refresh/
Unauthorized: /api/user/profile/
Bad Request: /api/token/refresh/
Not Found: /
Not Found: /
Not Found: /
Not Found: /
Not Found: /
Not Found: /
Not Found: /
Not Found: /
Not Found: /
Not Found: /
Not Found: /
Unauthorized: /api/user/profile/
Bad Request: /api/token/refresh/
Unauthorized: /api/homepage/
Unauthorized: /api/user/shipping-address/
Unauthorized: /api/user/profile/
Unauthorized: /api/user/order/
Unauthorized: /api/user/review/
Not Found: /api/remove_cart_item/131/
Not Found: /
Not Found: /
Not Found: /
Not Found: /
Not Found: /
Not Found: /
Unauthorized: /api/user/profile/
Unauthorized: /api/user/profile/
Bad Request: /api/token/refresh/
Bad Request: /api/token/refresh/
[UID:4986][946457] Child process with pid: 1048344 was killed by signal: 15, core dump: 0
Unauthorized: /api/create/cart/
Unauthorized: /api/create/cart/
Unauthorized: /api/token/refresh/
Unauthorized: /api/token/refresh/
Not Found: /api/reduce_quantity/114/
Not Found: /api/reduce_quantity/114/
Unauthorized: /api/create/cart/
Unauthorized: /api/create/cart/
Bad Request: /api/token/refresh/
Bad Request: /api/token/refresh/
Unauthorized: /api/user/profile/
Unauthorized: /api/user/profile/
Bad Request: /api/token/refresh/
Bad Request: /api/token/refresh/
Unauthorized: /api/user/profile/
Bad Request: /api/token/refresh/
Unauthorized: /api/user/profile/
Bad Request: /api/token/refresh/
Unauthorized: /api/add_to_cart/20/
Bad Request: /api/token/refresh/
Unauthorized: /api/create/cart/
Unauthorized: /api/create/cart/
Bad Request: /api/token/refresh/
Bad Request: /api/token/refresh/
Unauthorized: /api/user/profile/
Unauthorized: /api/user/profile/
Bad Request: /api/token/refresh/
Bad Request: /api/token/refresh/
Unauthorized: /api/user/profile/
Bad Request: /api/token/refresh/
Unauthorized: /api/user/profile/
Bad Request: /api/token/refresh/
Unauthorized: /api/add_to_cart/20/
Bad Request: /api/token/refresh/
Unauthorized: /api/add_to_cart/20/
Bad Request: /api/token/refresh/
Unauthorized: /api/user/profile/
Unauthorized: /api/user/shipping-address/
Not Found: /api/user/order/
Unauthorized: /api/user/review/
Unauthorized: /api/user/profile/
Unauthorized: /api/user/shipping-address/
Not Found: /api/user/order/
Bad Request: /api/token/refresh/
Unauthorized: /api/user/review/
Bad Request: /api/token/refresh/
Bad Request: /api/token/refresh/
Bad Request: /api/token/refresh/
Bad Request: /api/token/refresh/
Bad Request: /api/token/refresh/
Unauthorized: /api/create/cart/
Unauthorized: /api/create/cart/
Bad Request: /api/token/refresh/
Bad Request: /api/token/refresh/
[UID:4986][946457] Child process with pid: 1140350 was killed by signal: 15, core dump: 0
Not Found: /
Not Found: /
Not Found: /
Not Found: /
Not Found: /
Not Found: /
Not Found: /
Not Found: /
Not Found: /
Not Found: /
Not Found: /
Not Found: /
Unauthorized: /api/user/profile/
Unauthorized: /api/token/blacklist/
Unauthorized: /api/admin/list/product/
Bad Request: /api/token/refresh/
Bad Request: /api/token/
Not Found: /api/index.php/v1/config/application
Not Found: /
Not Found: /
Not Found: /
Not Found: /
Not Found: /
Not Found: /
Not Found: /
Not Found: /
Not Found: /
Not Found: /
Not Found: /
Not Found: /.aws/credentials
Not Found: /.aws/credentials
Not Found: /
Not Found: /
Not Found: /
Not Found: /
Not Found: /
Not Found: /
Not Found: /
Not Found: /
Not Found: /
Not Found: /
Not Found: /
Not Found: /
Not Found: /
Not Found: /
Not Found: /
Not Found: /
Not Found: /
Not Found: /
Not Found: /
Not Found: /
Not Found: /
Not Found: /
Not Found: /
Not Found: /
Not Found: /
Not Found: /
Not Found: /
Not Found: /
Not Found: /
Not Found: /
Unauthorized: /api/user/profile/
Bad Request: /api/token/refresh/
Unauthorized: /api/user/profile/
Bad Request: /api/token/refresh/
Unauthorized: /api/user/profile/
Unauthorized: /api/user/profile/
Bad Request: /api/token/refresh/
Bad Request: /api/token/refresh/
[UID:4986][2949370] Child process with pid: 3631743 was killed by signal: 15, core dump: 0
Unauthorized: /api/add_to_cart/20/
Unauthorized: /api/add_to_cart/20/
Unauthorized: /api/reduce_quantity/132/
[UID:4986][871276] Reached max children process limit: 6, extra: 2, current: 8, busy: 7, please increase LSAPI_CHILDREN.
[UID:4986][871276] Reached max children process limit: 6, extra: 2, current: 8, busy: 8, please increase LSAPI_CHILDREN.
[UID:4986][871276] Reached max children process limit: 6, extra: 2, current: 8, busy: 8, please increase LSAPI_CHILDREN.
[UID:4986][871276] Reached max children process limit: 6, extra: 2, current: 8, busy: 8, please increase LSAPI_CHILDREN.
[UID:4986][871276] Reached max children process limit: 6, extra: 2, current: 8, busy: 8, please increase LSAPI_CHILDREN.
[UID:4986][871276] Reached max children process limit: 6, extra: 2, current: 8, busy: 7, please increase LSAPI_CHILDREN.
Unauthorized: /api/create/order/
Unauthorized: /api/list/cart-item/
Unauthorized: /api/list/shipping-address/
Not Found: /
Not Found: /
Not Found: /
Not Found: /
Not Found: /
Not Found: /
Not Found: /
Unauthorized: /api/homepage/
Unauthorized: /api/homepage/
Unauthorized: /api/homepage/
Unauthorized: /api/homepage/
Unauthorized: /api/homepage/
Unauthorized: /api/products/agate-beads/reviews/
Unauthorized: /api/product/agate-beads/
Unauthorized: /api/user/profile/
Unauthorized: /api/user/profile/
Unauthorized: /api/user/profile/
Bad Request: /api/token/refresh/
Bad Request: /api/token/refresh/
Unauthorized: /api/user/profile/
Unauthorized: /api/user/profile/
Bad Request: /api/token/refresh/
Bad Request: /api/token/refresh/
Not Found: /
Unauthorized: /api/token/blacklist/
Unauthorized: /api/user/profile/
Not Found: /
Not Found: /favicon.ico
Unauthorized: /api/homepage/
Unauthorized: /api/list/categories/product/
Not Found: /
Not Found: /
Not Found: /
Not Found: /
Unauthorized: /api/user/profile/
Bad Request: /api/token/refresh/
Unauthorized: /api/homepage/
Unauthorized: /api/homepage/
Unauthorized: /api/token/refresh/
Unauthorized: /api/token/refresh/
Bad Request: /api/token/blacklist/
Bad Request: /api/token/blacklist/
Unauthorized: /api/user/profile/
Unauthorized: /api/user/shipping-address/
Not Found: /api/user/order/
Unauthorized: /api/user/review/
Unauthorized: /api/user/profile/
Unauthorized: /api/user/shipping-address/
Bad Request: /api/token/refresh/
Bad Request: /api/token/refresh/
Not Found: /api/user/order/
Bad Request: /api/token/refresh/
Unauthorized: /api/user/review/
Bad Request: /api/token/refresh/
Bad Request: /api/token/refresh/
Bad Request: /api/token/refresh/
Unauthorized: /api/create/cart/
Unauthorized: /api/create/cart/
Bad Request: /api/token/refresh/
Bad Request: /api/token/refresh/
Unauthorized: /api/user/profile/
Unauthorized: /api/user/shipping-address/
Unauthorized: /api/user/review/
Not Found: /api/user/order/
Unauthorized: /api/user/profile/
Bad Request: /api/token/refresh/
Unauthorized: /api/user/shipping-address/
Unauthorized: /api/user/review/
Bad Request: /api/token/refresh/
Bad Request: /api/token/refresh/
Not Found: /api/user/order/
Bad Request: /api/token/refresh/
Bad Request: /api/token/refresh/
Bad Request: /api/token/refresh/
Unauthorized: /api/create/cart/
Unauthorized: /api/create/cart/
Bad Request: /api/token/refresh/
Bad Request: /api/token/refresh/
Unauthorized: /api/user/review/
Not Found: /api/user/order/
Unauthorized: /api/user/profile/
Unauthorized: /api/user/shipping-address/
Not Found: /api/user/order/
Unauthorized: /api/user/profile/
Unauthorized: /api/user/review/
Bad Request: /api/token/refresh/
Bad Request: /api/token/refresh/
Unauthorized: /api/user/shipping-address/
Bad Request: /api/token/refresh/
Bad Request: /api/token/refresh/
Bad Request: /api/token/refresh/
Bad Request: /api/token/refresh/
Unauthorized: /api/user/profile/
Bad Request: /api/token/refresh/
Unauthorized: /api/user/profile/
Bad Request: /api/token/refresh/
Unauthorized: /api/user/profile/
Bad Request: /api/token/refresh/
Not Found: /
Unauthorized: /api/homepage/
Unauthorized: /api/user/profile/
Bad Request: /api/token/refresh/
Unauthorized: /api/list/categories/product/
Unauthorized: /api/user/profile/
Bad Request: /api/token/refresh/
Unauthorized: /api/homepage/
Unauthorized: /api/homepage/
Unauthorized: /api/homepage/
Unauthorized: /api/homepage/
Unauthorized: /api/homepage/
Unauthorized: /api/homepage/
Not Found: /favicon.ico
Unauthorized: /api/list/category/
Unauthorized: /api/about-us/
Unauthorized: /api/homepage/
Unauthorized: /api/about-us/
Unauthorized: /api/homepage/
Unauthorized: /api/about-us/
Unauthorized: /api/about-us/
Unauthorized: /api/user/profile/
[UID:4986][2728575] Reached max children process limit: 6, extra: 2, current: 8, busy: 7, please increase LSAPI_CHILDREN.
[UID:4986][2728575] Reached max children process limit: 6, extra: 2, current: 8, busy: 8, please increase LSAPI_CHILDREN.
[UID:4986][2728575] Reached max children process limit: 6, extra: 2, current: 8, busy: 8, please increase LSAPI_CHILDREN.
[UID:4986][2728575] Reached max children process limit: 6, extra: 2, current: 8, busy: 8, please increase LSAPI_CHILDREN.
[UID:4986][2728575] Reached max children process limit: 6, extra: 2, current: 8, busy: 8, please increase LSAPI_CHILDREN.
Unauthorized: /api/homepage/
Unauthorized: /api/list/categories/product/
Unauthorized: /api/about-us/
Unauthorized: /api/homepage/
Unauthorized: /api/about-us/
Unauthorized: /api/list/categories/product/
Unauthorized: /api/about-us/
Unauthorized: /api/about-us/
Unauthorized: /api/homepage/
Unauthorized: /api/homepage/
[UID:4986][2586431] Reached max children process limit: 6, extra: 2, current: 8, busy: 7, please increase LSAPI_CHILDREN.
[UID:4986][2586431] Reached max children process limit: 6, extra: 2, current: 8, busy: 8, please increase LSAPI_CHILDREN.
[UID:4986][2586431] Reached max children process limit: 6, extra: 2, current: 8, busy: 8, please increase LSAPI_CHILDREN.
[UID:4986][2586431] Reached max children process limit: 6, extra: 2, current: 8, busy: 8, please increase LSAPI_CHILDREN.
[UID:4986][2586431] Reached max children process limit: 6, extra: 2, current: 8, busy: 8, please increase LSAPI_CHILDREN.
[UID:4986][2586431] Reached max children process limit: 6, extra: 2, current: 8, busy: 8, please increase LSAPI_CHILDREN.
[UID:4986][2586431] Reached max children process limit: 6, extra: 2, current: 8, busy: 8, please increase LSAPI_CHILDREN.
Unauthorized: /api/list/categories/product/
Unauthorized: /api/list/categories/product/
Unauthorized: /api/list/categories/product/
Unauthorized: /api/list/categories/product/
Unauthorized: /api/list/categories/product/
Unauthorized: /api/user/profile/
Not Found: /
Unauthorized: /api/list/categories/product/
Unauthorized: /api/list/categories/product/
Not Found: /
Unauthorized: /api/create/cart/
Unauthorized: /api/create/cart/
Unauthorized: /api/create/cart/
Unauthorized: /api/homepage/
Unauthorized: /api/homepage/
Unauthorized: /api/user/profile/
Bad Request: /api/token/refresh/
Not Found: /
Unauthorized: /api/user/profile/
Bad Request: /api/token/refresh/
Not Found: /
Not Found: /
Unauthorized: /api/user/profile/
[UID:4986][4191382] Child process with pid: 10185 was killed by signal: 15, core dump: 0
Bad Request: /api/token/blacklist/
Not Found: /
Unauthorized: /api/token/blacklist/
Unauthorized: /api/homepage/
Unauthorized: /api/homepage/
Not Found: /
Exception ignored in: <_io.TextIOWrapper name='<stdout>' mode='w' encoding='utf-8'>
BrokenPipeError: [Errno 32] Broken pipe
Exception ignored in: <_io.TextIOWrapper name='<stdout>' mode='w' encoding='utf-8'>
BrokenPipeError: [Errno 32] Broken pipe
Exception ignored in: <_io.TextIOWrapper name='<stdout>' mode='w' encoding='utf-8'>
BrokenPipeError: [Errno 32] Broken pipe
Exception ignored in: <_io.TextIOWrapper name='<stdout>' mode='w' encoding='utf-8'>
BrokenPipeError: [Errno 32] Broken pipe
Exception ignored in: <_io.TextIOWrapper name='<stdout>' mode='w' encoding='utf-8'>
BrokenPipeError: [Errno 32] Broken pipe
Exception ignored in: <_io.TextIOWrapper name='<stdout>' mode='w' encoding='utf-8'>
BrokenPipeError: [Errno 32] Broken pipe
Exception ignored in: <_io.TextIOWrapper name='<stdout>' mode='w' encoding='utf-8'>
BrokenPipeError: [Errno 32] Broken pipe
Not Found: /
Not Found: /
Not Found: /
Not Found: /
Not Found: /
Unauthorized: /api/homepage/
Not Found: /
Not Found: /
Not Found: /
Not Found: /
Exception ignored in: <_io.TextIOWrapper name='<stdout>' mode='w' encoding='utf-8'>
BrokenPipeError: [Errno 32] Broken pipe
Exception ignored in: <_io.TextIOWrapper name='<stdout>' mode='w' encoding='utf-8'>
BrokenPipeError: [Errno 32] Broken pipe
Exception ignored in: <_io.TextIOWrapper name='<stdout>' mode='w' encoding='utf-8'>
BrokenPipeError: [Errno 32] Broken pipe
Exception ignored in: <_io.TextIOWrapper name='<stdout>' mode='w' encoding='utf-8'>
BrokenPipeError: [Errno 32] Broken pipe
Exception ignored in: <_io.TextIOWrapper name='<stdout>' mode='w' encoding='utf-8'>
BrokenPipeError: [Errno 32] Broken pipe
Exception ignored in: <_io.TextIOWrapper name='<stdout>' mode='w' encoding='utf-8'>
BrokenPipeError: [Errno 32] Broken pipe
Exception ignored in: <_io.TextIOWrapper name='<stdout>' mode='w' encoding='utf-8'>
BrokenPipeError: [Errno 32] Broken pipe
Exception ignored in: <_io.TextIOWrapper name='<stdout>' mode='w' encoding='utf-8'>
BrokenPipeError: [Errno 32] Broken pipe
Exception ignored in: <_io.TextIOWrapper name='<stdout>' mode='w' encoding='utf-8'>
BrokenPipeError: [Errno 32] Broken pipe
Exception ignored in: <_io.TextIOWrapper name='<stdout>' mode='w' encoding='utf-8'>
BrokenPipeError: [Errno 32] Broken pipe
Exception ignored in: <_io.TextIOWrapper name='<stdout>' mode='w' encoding='utf-8'>
BrokenPipeError: [Errno 32] Broken pipe
Exception ignored in: <_io.TextIOWrapper name='<stdout>' mode='w' encoding='utf-8'>
BrokenPipeError: [Errno 32] Broken pipe
Exception ignored in: <_io.TextIOWrapper name='<stdout>' mode='w' encoding='utf-8'>
BrokenPipeError: [Errno 32] Broken pipe
Exception ignored in: <_io.TextIOWrapper name='<stdout>' mode='w' encoding='utf-8'>
BrokenPipeError: [Errno 32] Broken pipe
Exception ignored in: <_io.TextIOWrapper name='<stdout>' mode='w' encoding='utf-8'>
BrokenPipeError: [Errno 32] Broken pipe
Exception ignored in: <_io.TextIOWrapper name='<stdout>' mode='w' encoding='utf-8'>
BrokenPipeError: [Errno 32] Broken pipe
Not Found: /
Not Found: /
Not Found: /
Not Found: /favicon.ico
Not Found: /
Not Found: /
Not Found: /
Not Found: /
Not Found: /
Not Found: /
Exception ignored in: <_io.TextIOWrapper name='<stdout>' mode='w' encoding='utf-8'>
BrokenPipeError: [Errno 32] Broken pipe
Error blacklisting refresh token: Token is blacklisted
Exception ignored in: <_io.TextIOWrapper name='<stdout>' mode='w' encoding='utf-8'>
BrokenPipeError: [Errno 32] Broken pipe
Exception ignored in: <_io.TextIOWrapper name='<stdout>' mode='w' encoding='utf-8'>
BrokenPipeError: [Errno 32] Broken pipe
Exception ignored in: <_io.TextIOWrapper name='<stdout>' mode='w' encoding='utf-8'>
BrokenPipeError: [Errno 32] Broken pipe
Exception ignored in: <_io.TextIOWrapper name='<stdout>' mode='w' encoding='utf-8'>
BrokenPipeError: [Errno 32] Broken pipe
Exception ignored in: <_io.TextIOWrapper name='<stdout>' mode='w' encoding='utf-8'>
BrokenPipeError: [Errno 32] Broken pipe
Exception ignored in: <_io.TextIOWrapper name='<stdout>' mode='w' encoding='utf-8'>
BrokenPipeError: [Errno 32] Broken pipe
Exception ignored in: <_io.TextIOWrapper name='<stdout>' mode='w' encoding='utf-8'>
BrokenPipeError: [Errno 32] Broken pipe
Exception ignored in: <_io.TextIOWrapper name='<stdout>' mode='w' encoding='utf-8'>
BrokenPipeError: [Errno 32] Broken pipe
Exception ignored in: <_io.TextIOWrapper name='<stdout>' mode='w' encoding='utf-8'>
BrokenPipeError: [Errno 32] Broken pipe
Exception ignored in: <_io.TextIOWrapper name='<stdout>' mode='w' encoding='utf-8'>
BrokenPipeError: [Errno 32] Broken pipe
Exception ignored in: <_io.TextIOWrapper name='<stdout>' mode='w' encoding='utf-8'>
BrokenPipeError: [Errno 32] Broken pipe
Exception ignored in: <_io.TextIOWrapper name='<stdout>' mode='w' encoding='utf-8'>
BrokenPipeError: [Errno 32] Broken pipe
Exception ignored in: <_io.TextIOWrapper name='<stdout>' mode='w' encoding='utf-8'>
BrokenPipeError: [Errno 32] Broken pipe
Exception ignored in: <_io.TextIOWrapper name='<stdout>' mode='w' encoding='utf-8'>
BrokenPipeError: [Errno 32] Broken pipe
Exception ignored in: <_io.TextIOWrapper name='<stdout>' mode='w' encoding='utf-8'>
BrokenPipeError: [Errno 32] Broken pipe
Exception ignored in: <_io.TextIOWrapper name='<stdout>' mode='w' encoding='utf-8'>
BrokenPipeError: [Errno 32] Broken pipe
Exception ignored in: <_io.TextIOWrapper name='<stdout>' mode='w' encoding='utf-8'>
BrokenPipeError: [Errno 32] Broken pipe
Exception ignored in: <_io.TextIOWrapper name='<stdout>' mode='w' encoding='utf-8'>
BrokenPipeError: [Errno 32] Broken pipe
Exception ignored in: <_io.TextIOWrapper name='<stdout>' mode='w' encoding='utf-8'>
BrokenPipeError: [Errno 32] Broken pipe
Exception ignored in: <_io.TextIOWrapper name='<stdout>' mode='w' encoding='utf-8'>
BrokenPipeError: [Errno 32] Broken pipe
Exception ignored in: <_io.TextIOWrapper name='<stdout>' mode='w' encoding='utf-8'>
BrokenPipeError: [Errno 32] Broken pipe
Exception ignored in: <_io.TextIOWrapper name='<stdout>' mode='w' encoding='utf-8'>
BrokenPipeError: [Errno 32] Broken pipe
Exception ignored in: <_io.TextIOWrapper name='<stdout>' mode='w' encoding='utf-8'>
BrokenPipeError: [Errno 32] Broken pipe
Exception ignored in: <_io.TextIOWrapper name='<stdout>' mode='w' encoding='utf-8'>
BrokenPipeError: [Errno 32] Broken pipe
Exception ignored in: <_io.TextIOWrapper name='<stdout>' mode='w' encoding='utf-8'>
BrokenPipeError: [Errno 32] Broken pipe
Exception ignored in: <_io.TextIOWrapper name='<stdout>' mode='w' encoding='utf-8'>
BrokenPipeError: [Errno 32] Broken pipe
Exception ignored in: <_io.TextIOWrapper name='<stdout>' mode='w' encoding='utf-8'>
BrokenPipeError: [Errno 32] Broken pipe
Exception ignored in: <_io.TextIOWrapper name='<stdout>' mode='w' encoding='utf-8'>
BrokenPipeError: [Errno 32] Broken pipe
Exception ignored in: <_io.TextIOWrapper name='<stdout>' mode='w' encoding='utf-8'>
BrokenPipeError: [Errno 32] Broken pipe
Exception ignored in: <_io.TextIOWrapper name='<stdout>' mode='w' encoding='utf-8'>
BrokenPipeError: [Errno 32] Broken pipe
Exception ignored in: <_io.TextIOWrapper name='<stdout>' mode='w' encoding='utf-8'>
BrokenPipeError: [Errno 32] Broken pipe
Exception ignored in: <_io.TextIOWrapper name='<stdout>' mode='w' encoding='utf-8'>
BrokenPipeError: [Errno 32] Broken pipe
Exception ignored in: <_io.TextIOWrapper name='<stdout>' mode='w' encoding='utf-8'>
BrokenPipeError: [Errno 32] Broken pipe
Exception ignored in: <_io.TextIOWrapper name='<stdout>' mode='w' encoding='utf-8'>
BrokenPipeError: [Errno 32] Broken pipe
[UID:4986][4882] Child process with pid: 5540 was killed by signal: 15, core dump: 0
Exception ignored in: <_io.TextIOWrapper name='<stdout>' mode='w' encoding='utf-8'>
BrokenPipeError: [Errno 32] Broken pipe
Exception ignored in: <_io.TextIOWrapper name='<stdout>' mode='w' encoding='utf-8'>
BrokenPipeError: [Errno 32] Broken pipe
Exception ignored in: <_io.TextIOWrapper name='<stdout>' mode='w' encoding='utf-8'>
BrokenPipeError: [Errno 32] Broken pipe
Exception ignored in: <_io.TextIOWrapper name='<stdout>' mode='w' encoding='utf-8'>
BrokenPipeError: [Errno 32] Broken pipe
Exception ignored in: <_io.TextIOWrapper name='<stdout>' mode='w' encoding='utf-8'>
BrokenPipeError: [Errno 32] Broken pipe
Exception ignored in: <_io.TextIOWrapper name='<stdout>' mode='w' encoding='utf-8'>
BrokenPipeError: [Errno 32] Broken pipe
Exception ignored in: <_io.TextIOWrapper name='<stdout>' mode='w' encoding='utf-8'>
BrokenPipeError: [Errno 32] Broken pipe
Exception ignored in: <_io.TextIOWrapper name='<stdout>' mode='w' encoding='utf-8'>
BrokenPipeError: [Errno 32] Broken pipe
Exception ignored in: <_io.TextIOWrapper name='<stdout>' mode='w' encoding='utf-8'>
BrokenPipeError: [Errno 32] Broken pipe
Exception ignored in: <_io.TextIOWrapper name='<stdout>' mode='w' encoding='utf-8'>
BrokenPipeError: [Errno 32] Broken pipe
Exception ignored in: <_io.TextIOWrapper name='<stdout>' mode='w' encoding='utf-8'>
BrokenPipeError: [Errno 32] Broken pipe
Exception ignored in: <_io.TextIOWrapper name='<stdout>' mode='w' encoding='utf-8'>
BrokenPipeError: [Errno 32] Broken pipe
Exception ignored in: <_io.TextIOWrapper name='<stdout>' mode='w' encoding='utf-8'>
BrokenPipeError: [Errno 32] Broken pipe
Exception ignored in: <_io.TextIOWrapper name='<stdout>' mode='w' encoding='utf-8'>
BrokenPipeError: [Errno 32] Broken pipe
Exception ignored in: <_io.TextIOWrapper name='<stdout>' mode='w' encoding='utf-8'>
BrokenPipeError: [Errno 32] Broken pipe
Exception ignored in: <_io.TextIOWrapper name='<stdout>' mode='w' encoding='utf-8'>
BrokenPipeError: [Errno 32] Broken pipe
Exception ignored in: <_io.TextIOWrapper name='<stdout>' mode='w' encoding='utf-8'>
BrokenPipeError: [Errno 32] Broken pipe
Exception ignored in: <_io.TextIOWrapper name='<stdout>' mode='w' encoding='utf-8'>
BrokenPipeError: [Errno 32] Broken pipe
Exception ignored in: <_io.TextIOWrapper name='<stdout>' mode='w' encoding='utf-8'>
BrokenPipeError: [Errno 32] Broken pipe
Exception ignored in: <_io.TextIOWrapper name='<stdout>' mode='w' encoding='utf-8'>
BrokenPipeError: [Errno 32] Broken pipe
Exception ignored in: <_io.TextIOWrapper name='<stdout>' mode='w' encoding='utf-8'>
BrokenPipeError: [Errno 32] Broken pipe
Exception ignored in: <_io.TextIOWrapper name='<stdout>' mode='w' encoding='utf-8'>
BrokenPipeError: [Errno 32] Broken pipe
Exception ignored in: <_io.TextIOWrapper name='<stdout>' mode='w' encoding='utf-8'>
BrokenPipeError: [Errno 32] Broken pipe
